Workbook

Sheet Mon
A1: Republic Hotel - Daily Takings
A2: MONDAY
K3: DATE: | L3: 46055 | N3: SUNDRIES | Q3: FOOD
A4: BISTRO | B4: READING | C4: FOOD | D4: TYRO FEE | E4: TIPS | F4: EXPECTED | G4: EFTPOS | H4: AMEX/DINER | I4: ME&U | J4: CASH | K4: VAR (+ / -) | L4: ACCOUNT | Q4: =A4 -> BISTRO | R4: =C8 -> 0
F5: =B5-(D5+L5) -> 0 | K5: =SUM(I5+J5+H5+G5)-F5 -> 0 | Q5: =A11 -> SPORTS BAR | R5: =C15 -> 0
F6: =B6-(D6+L6) -> 0 | K6: =SUM(I6+J6+H6+G6)-F6 -> 0 | Q6: BALCONY | R6: =C22+C28 -> 0
F7: =B7-(D7+L7) -> 0 | K7: =SUM(I7+J7+H7+G7)-F7 -> 0 | N7: TOTAL | O7: =O4+O5+O6 -> 0 | Q7: PUBLIC 1 / 2 | R7: =+C36+C42 -> 0
A8: TOTALS | B8: =SUM(B5:B7) -> 0 | C8: =SUM(C5:C7) -> 0 | D8: =SUM(D5:D7) -> 0 | E8: =SUM(E5:E7) -> 0 | F8: =SUM(F5:F7) -> 0 | G8: =SUM(G5:G7) -> 0 | H8: =SUM(H5:H7) -> 0 | I8: =SUM(I5:I7) -> 0 | J8: =SUM(J5:J7) -> 0 | K8: =SUM(I8+J8+H8+G8)-F8 -> 0 | L8: =SUM(L5:L7) -> 0 | Q8: BISTRO TILL | R8: =C57 -> 0
G9: BISTRO TOTAL | J9: =SUM(I8+J8+H8+G8)-C8-E8 -> 0 | Q9: TOTAL | R9: =SUM(R4:R8) -> 0
N10: TAB
A11: SPORTS BAR | B11: READING | C11: FOOD | D11: TYRO FEE | E11: TIPS | F11: EXPECTED | G11: EFTPOS | H11: AMEX/DINER | I11: ME&U | J11: CASH | K11: VAR (+ / -) | L11: ACCOUNT | N11: SALES | Q11: POKIES
F12: =B12-(D12+L12) -> 0 | K12: =SUM(I12+J12+H12+G12)-F12 -> 0 | N12: TERMINAL | O12: 0 | Q12: CASH BOX
F13: =B13-(D13+L13) -> 0 | K13: =SUM(I13+J13+H13+G13)-F13 -> 0 | N13: EBET 1 | Q13: TICKET IN
F14: =B14-(D14+L14) -> 0 | K14: =SUM(I14+J14+H14+G14)-F14 -> 0 | N14: EBET 2 | Q14: CASH IN | R14: =R12-R13 -> 0
A15: TOTALS | B15: =SUM(B12:B14) -> 0 | C15: =SUM(C12:C14) -> 0 | D15: =SUM(D12:D14) -> 0 | E15: =SUM(E12:E14) -> 0 | F15: =SUM(F12:F14) -> 0 | G15: =SUM(G12:G14) -> 0 | H15: =SUM(H12:H14) -> 0 | I15: =SUM(I12:I14) -> 0 | ... L15: =SUM(L12:L14) -> 0 | N15: TOTAL | O15: =SUM(O12:O14) -> 0 | Q15: MONEY OUT
G16: SPORTS BAR TOTAL | J16: =SUM(I15+J15+H15+G15)-C15-E15 -> 0 | N16: LIABILITY | Q16: LINK AUTO
N17: TERMINAL | Q17: LINK MAN
A18: PUBLIC 1 | B18: READING | C18: FOOD | D18: TYRO FEE | E18: TIPS | F18: EXPECTED | G18: EFTPOS | H18: AMEX/DINER | I18: ME&U | J18: CASH | K18: VAR (+ / -) | L18: ACCOUNT | N18: EBET 1 | Q18: C/CREDITS
F19: =B19-(D19+L19) -> 0 | K19: =SUM(I19+J19+H19+G19)-F19 -> 0 | N19: EBET 2 | Q19: NET | R19: =R12-R15-R17-R18 -> 0
F20: =B20-(D20+L20) -> 0 | K20: =SUM(I20+J20+H20+G20)-F20 -> 0 | N20: TOTAL | O20: =SUM(O17:O19) -> 0 | Q20: TURNOVER
F21: =B21-(D21+L21) -> 0 | K21: =SUM(I21+J21+H21+G21)-F21 -> 0
A22: TOTALS | B22: =SUM(B19:B21) -> 0 | C22: =SUM(C19:C21) -> 0 | D22: =SUM(D19:D21) -> 0 | E22: =SUM(E19:E21) -> 0 | F22: =SUM(F19:F21) -> 0 | G22: =SUM(G19:G21) -> 0 | H22: =SUM(H19:H21) -> 0 | I22: =SUM(I19:I21) -> 0 | ... L22: =SUM(L19:L21) -> 0 | N22: EFTPOS
N23: =A11 -> SPORTS BAR | O23: =G15 -> 0 | Q23: TOTALS
A24: PUBLIC 2/GAMING | B24: READING | C24: FOOD | D24: TYRO FEE | E24: TIPS | F24: EXPECTED | G24: EFTPOS | H24: AMEX/DINER | I24: ME&U | J24: CASH | K24: VAR (+ / -) | L24: ACCOUNT | N24: =A4 -> BISTRO | O24: =G8 -> 0 | Q24: RECEIPTS | R24: =SUM(J29,J51,O7,J43,J16,J9,R19,J58,R9) -> 0
F25: =B25-(D25+L25) -> 0 | K25: =SUM(I25+J25+H25+G25)-F25 -> 0 | N25: B/SHOP | O25: =G50 -> 0 | Q25: GST | R25: =ROUND(+R24/11,2) -> 0
F26: =B26-(D26+L26) -> 0 | K26: =SUM(I26+J26+H26+G26)-F26 -> 0 | N26: PUBLIC 1 | O26: =G22 -> 0 | Q26: ATM | R26: =R39 -> 0
F27: =B27-(D27+L27) -> 0 | K27: =SUM(I27+J27+H27+G27)-F27 -> 0 | N27: PUBLIC 2 | O27: =G28 -> 0 | Q27: ME&U | R27: =I57+I42+I36+I28+I22+I15+I8 -> 0
A28: TOTALS | B28: =SUM(B25:B27) -> 0 | C28: =SUM(C25:C27) -> 0 | D28: =SUM(D25:D27) -> 0 | E28: =SUM(E25:E27) -> 0 | F28: =SUM(F25:F27) -> 0 | G28: =SUM(G25:G27) -> 0 | H28: =SUM(H25:H27) -> 0 | I28: =SUM(I25:I27) -> 0 | ... L28: =SUM(L25:L27) -> 0 | N28: ROOF TOP 1 | O28: =G36 -> 0 | Q28: EFTPOS | R28: =O31 -> 0
G29: PUBLIC BAR TOTAL | J29: =SUM(G22+H22+I22+J22)+(I28+J28+H28+G28)-C28-E28-C22-E22 -> 0 | N29: ROOF TOP 2 | O29: =G42 -> 0 | Q29: BANKING | R29: =R24-(R28+R26+R27) -> 0
N30: BISTRO | O30: =G57 -> 0
A31: TAYLORS BAR | N31: TOTAL | O31: =SUM(O23:O30) -> 0 | Q31: TAKING TIN | R31: =J8+J15+J22+J28+J36+J42+J50+J57 -> 0
A32: ROOF TOP 1 | B32: READING | C32: FOOD | D32: TYRO FEE | E32: TIPS | F32: EXPECTED | G32: EFTPOS | H32: AMEX/DINER | I32: ME&U | J32: CASH | K32: VAR (+ / -) | L32: ACCOUNT
F33: =B33-(D33+L33) -> 0 | K33: =SUM(I33+J33+H33+G33)-F33 -> 0 | Q33: TAB (ATM)
F34: =B34-(D34+L34) -> 0 | K34: =SUM(I34+J34+H34+G34)-F34 -> 0
F35: =B35-(D35+L35) -> 0 | K35: =SUM(I35+J35+H35+G35)-F35 -> 0
A36: TOTALS | B36: =SUM(B33:B35) -> 0 | C36: =SUM(C33:C35) -> 0 | D36: =SUM(D33:D35) -> 0 | E36: =SUM(E33:E35) -> 0 | F36: =SUM(F33:F35) -> 0 | G36: =SUM(G33:G35) -> 0 | H36: =SUM(H33:H35) -> 0 | I36: =SUM(I33:I35) -> 0 | ... L36: =SUM(L33:L35) -> 0 | Q36: ATM REFILL
Q37: ATM 1
A38: ROOF TOP 2 | B38: READING | C38: FOOD | D38: TYRO FEE | E38: TIPS | F38: EXPECTED | G38: EFTPOS | H38: AMEX/DINER | I38: ME&U | J38: CASH | K38: VAR (+ / -) | L38: ACCOUNT | Q38: ATM 2
F39: =B39-(D39+L39) -> 0 | K39: =SUM(I39+J39+H39+G39)-F39 -> 0 | Q39: TOTAL | R39: =SUM(R37:R38) -> 0
F40: =B40-(D40+L40) -> 0 | K40: =SUM(I40+J40+H40+G40)-F40 -> 0
...

Sheet Mon diary
A1: Republic Hotel
A2: =Mon!L3 -> 46055
A3: Weather
A5: Summary | B5: Monday | F5: Bars | G5: =SUM(G6:G9) -> 0
A6: Gaming Turnover | B6: =Takings!B24 -> 0 | F6: Public | G6: =Takings!C5 -> 0
A7: Gaming Gross | B7: =Takings!C24 -> 0 | F7: Bistro | G7: =Takings!D5 -> 0
A8: Gaming Net | B8: =Takings!I5 -> 0 | F8: Sports | G8: =Takings!E5 -> 0
A9: Dragon Link (50K) | F9: Taylors | G9: =Takings!F5 -> 0
A10: Dragon Train (20K)
A11: Fortune Hearts (25K)
A12: Dragon Rush (90K)
A13: Dragon Link (90K)
A14: Thunder Empire (50K) | F14: Bistro & Food Service
A15: Power Panther (12K) | F15: Day Covers | G15: =B45 -> 0 | H15: Night Covers | I15: =D45 -> 0
A16: Bars | B16: =Takings!B46 -> 0 | F16: LUNCH Service Feedback
A17: Food | B17: =Takings!B49 -> 0
A18: Retail | B18: =Takings!H5 -> 0 | F18: Dinner Service Feedback
A19: TAB | B19: =Takings!L37 -> 0
F20: Public Bar
B21: DAY | C21: MID | D21: CLOSE | F21: Food | G21: =Mon!C22+Mon!C28 -> 0 | H21: Bev | I21: =Mon!J29 -> 0
A22: Managers Name | F22: Day
B23: GAMING
A24: Day turnover up to 6pm | B24: =G75 -> 0 | C24: Staff | F24: Evening
A25: How was the days trade
A26: Who were your big punters | F26: Late Night
A27: Large payouts/links & to whom
A28: Night turnover after 6pm | B28: =B6-B24 -> 0 | C28: Staff | F28: Bistro
A29: How was the night trade | F29: Food | G29: =Mon!C8 -> 0 | H29: Bev | I29: =Mon!J9 -> 0
A30: Who were your big punters | F30: Day
A31: Large payouts/links & to whom
B32: LINKS IF WON | F32: Evening
A33: What Link did they win
A34: How much was the Link | F34: Late Night
A35: What machine number
A36: How much were they betting | F36: Sports Bar
A37: Are they a regular | F37: Food | G37: =Mon!C15 -> 0 | H37: Bev | I37: =Mon!J16 -> 0
B38: AUSTRAC REPORTING | F38: Day
A39: Any Suspicious Customers
A40: Cash In to Turnover Ratio | B40: =Takings!B24/Takings!E24 -> #DIV/0! | F40: Evening
A41: Checked by
...

Sheet Tue
A1: Republic Hotel - Daily Takings
A2: TUESDAY
K3: DATE: | L3: =Mon!L3+1 -> 46056 | N3: SUNDRIES | Q3: FOOD
A4: BISTRO | B4: READING | C4: FOOD | D4: TYRO FEE | E4: TIPS | F4: EXPECTED | G4: EFTPOS | H4: AMEX/DINER | I4: ME&U | J4: CASH | K4: VAR (+ / -) | L4: ACCOUNT | Q4: =A4 -> BISTRO | R4: =C8 -> 0
F5: =B5-(D5+L5) -> 0 | K5: =SUM(I5+J5+H5+G5)-F5 -> 0 | Q5: =A11 -> SPORTS BAR | R5: =C15 -> 0
F6: =B6-(D6+L6) -> 0 | K6: =SUM(I6+J6+H6+G6)-F6 -> 0 | Q6: BALCONY | R6: =C22+C28 -> 0
F7: =B7-(D7+L7) -> 0 | K7: =SUM(I7+J7+H7+G7)-F7 -> 0 | N7: TOTAL | O7: =O4+O5+O6 -> 0 | Q7: PUBLIC 1 / 2 | R7: =+C36+C42 -> 0
A8: TOTALS | B8: =SUM(B5:B7) -> 0 | C8: =SUM(C5:C7) -> 0 | D8: =SUM(D5:D7) -> 0 | E8: =SUM(E5:E7) -> 0 | F8: =SUM(F5:F7) -> 0 | G8: =SUM(G5:G7) -> 0 | H8: =SUM(H5:H7) -> 0 | I8: =SUM(I5:I7) -> 0 | J8: =SUM(J5:J7) -> 0 | K8: =SUM(I8+J8+H8+G8)-F8 -> 0 | L8: =SUM(L5:L7) -> 0 | Q8: BISTRO TILL | R8: =C57 -> 0
G9: BISTRO TOTAL | J9: =SUM(I8+J8+H8+G8)-C8-E8 -> 0 | Q9: TOTAL | R9: =SUM(R4:R8) -> 0
N10: TAB
A11: SPORTS BAR | B11: READING | C11: FOOD | D11: TYRO FEE | E11: TIPS | F11: EXPECTED | G11: EFTPOS | H11: AMEX/DINER | I11: ME&U | J11: CASH | K11: VAR (+ / -) | L11: ACCOUNT | N11: SALES | Q11: POKIES
F12: =B12-(D12+L12) -> 0 | K12: =SUM(I12+J12+H12+G12)-F12 -> 0 | N12: TERMINAL | Q12: CASH BOX
F13: =B13-(D13+L13) -> 0 | K13: =SUM(I13+J13+H13+G13)-F13 -> 0 | N13: EBET 1 | Q13: TICKET IN
F14: =B14-(D14+L14) -> 0 | K14: =SUM(I14+J14+H14+G14)-F14 -> 0 | N14: EBET 2 | Q14: CASH IN | R14: =R12-R13 -> 0
A15: TOTALS | B15: =SUM(B12:B14) -> 0 | C15: =SUM(C12:C14) -> 0 | D15: =SUM(D12:D14) -> 0 | E15: =SUM(E12:E14) -> 0 | F15: =SUM(F12:F14) -> 0 | G15: =SUM(G12:G14) -> 0 | H15: =SUM(H12:H14) -> 0 | I15: =SUM(I12:I14) -> 0 | ... L15: =SUM(L12:L14) -> 0 | N15: TOTAL | O15: =SUM(O12:O14) -> 0 | Q15: MONEY OUT
G16: SPORTS BAR TOTAL | J16: =SUM(I15+J15+H15+G15)-C15-E15 -> 0 | N16: LIABILITY | Q16: LINK AUTO
N17: TERMINAL | Q17: LINK MAN
A18: PUBLIC 1 | B18: READING | C18: FOOD | D18: TYRO FEE | E18: TIPS | F18: EXPECTED | G18: EFTPOS | H18: AMEX/DINER | I18: ME&U | J18: CASH | K18: VAR (+ / -) | L18: ACCOUNT | N18: EBET 1 | Q18: C/CREDITS
F19: =B19-(D19+L19) -> 0 | K19: =SUM(I19+J19+H19+G19)-F19 -> 0 | N19: EBET 2 | Q19: NET | R19: =R12-R15-R17-R18 -> 0
F20: =B20-(D20+L20) -> 0 | K20: =SUM(I20+J20+H20+G20)-F20 -> 0 | N20: TOTAL | O20: =SUM(O17:O19) -> 0 | Q20: TURNOVER
F21: =B21-(D21+L21) -> 0 | K21: =SUM(I21+J21+H21+G21)-F21 -> 0
A22: TOTALS | B22: =SUM(B19:B21) -> 0 | C22: =SUM(C19:C21) -> 0 | D22: =SUM(D19:D21) -> 0 | E22: =SUM(E19:E21) -> 0 | F22: =SUM(F19:F21) -> 0 | G22: =SUM(G19:G21) -> 0 | H22: =SUM(H19:H21) -> 0 | I22: =SUM(I19:I21) -> 0 | ... L22: =SUM(L19:L21) -> 0 | N22: EFTPOS
N23: =A11 -> SPORTS BAR | O23: =G15 -> 0 | Q23: TOTALS
A24: PUBLIC 2/GAMING | B24: READING | C24: FOOD | D24: TYRO FEE | E24: TIPS | F24: EXPECTED | G24: EFTPOS | H24: AMEX/DINER | I24: ME&U | J24: CASH | K24: VAR (+ / -) | L24: ACCOUNT | N24: =A4 -> BISTRO | O24: =G8 -> 0 | Q24: RECEIPTS | R24: =SUM(J29,J51,O7,J43,J16,J9,R19,J58,R9) -> 0
F25: =B25-(D25+L25) -> 0 | K25: =SUM(I25+J25+H25+G25)-F25 -> 0 | N25: B/SHOP | O25: =G50 -> 0 | Q25: GST | R25: =ROUND(+R24/11,2) -> 0
F26: =B26-(D26+L26) -> 0 | K26: =SUM(I26+J26+H26+G26)-F26 -> 0 | N26: PUBLIC 1 | O26: =G22 -> 0 | Q26: ATM | R26: =R39 -> 0
F27: =B27-(D27+L27) -> 0 | K27: =SUM(I27+J27+H27+G27)-F27 -> 0 | N27: PUBLIC 2 | O27: =G28 -> 0 | Q27: ME&U | R27: =I57+I42+I36+I28+I22+I15+I8 -> 0
A28: TOTALS | B28: =SUM(B25:B27) -> 0 | C28: =SUM(C25:C27) -> 0 | D28: =SUM(D25:D27) -> 0 | E28: =SUM(E25:E27) -> 0 | F28: =SUM(F25:F27) -> 0 | G28: =SUM(G25:G27) -> 0 | H28: =SUM(H25:H27) -> 0 | I28: =SUM(I25:I27) -> 0 | ... L28: =SUM(L25:L27) -> 0 | N28: ROOF TOP 1 | O28: =G36 -> 0 | Q28: EFTPOS | R28: =O31 -> 0
G29: PUBLIC BAR TOTAL | J29: =SUM(G22+H22+I22+J22)+(I28+J28+H28+G28)-C28-E28-C22-E22 -> 0 | N29: ROOF TOP 2 | O29: =G42 -> 0 | Q29: BANKING | R29: =R24-(R28+R26+R27) -> 0
N30: BISTRO | O30: =G57 -> 0
A31: TAYLORS BAR | N31: TOTAL | O31: =SUM(O23:O30) -> 0 | Q31: TAKING TIN | R31: =J8+J15+J22+J28+J36+J42+J50+J57 -> 0
A32: ROOF TOP 1 | B32: READING | C32: FOOD | D32: TYRO FEE | E32: TIPS | F32: EXPECTED | G32: EFTPOS | H32: AMEX/DINER | I32: ME&U | J32: CASH | K32: VAR (+ / -) | L32: ACCOUNT
F33: =B33-(D33+L33) -> 0 | K33: =SUM(I33+J33+H33+G33)-F33 -> 0 | Q33: TAB (ATM)
F34: =B34-(D34+L34) -> 0 | K34: =SUM(I34+J34+H34+G34)-F34 -> 0
F35: =B35-(D35+L35) -> 0 | K35: =SUM(I35+J35+H35+G35)-F35 -> 0
A36: TOTALS | B36: =SUM(B33:B35) -> 0 | C36: =SUM(C33:C35) -> 0 | D36: =SUM(D33:D35) -> 0 | E36: =SUM(E33:E35) -> 0 | F36: =SUM(F33:F35) -> 0 | G36: =SUM(G33:G35) -> 0 | H36: =SUM(H33:H35) -> 0 | I36: =SUM(I33:I35) -> 0 | ... L36: =SUM(L33:L35) -> 0 | Q36: ATM REFILL
Q37: ATM 1
A38: ROOF TOP 2 | B38: READING | C38: FOOD | D38: TYRO FEE | E38: TIPS | F38: EXPECTED | G38: EFTPOS | H38: AMEX/DINER | I38: ME&U | J38: CASH | K38: VAR (+ / -) | L38: ACCOUNT | Q38: ATM 2
F39: =B39-(D39+L39) -> 0 | K39: =SUM(I39+J39+H39+G39)-F39 -> 0 | Q39: TOTAL | R39: =SUM(R37:R38) -> 0
F40: =B40-(D40+L40) -> 0 | K40: =SUM(I40+J40+H40+G40)-F40 -> 0
...

Sheet Tue diary
A1: Republic Hotel
A2: =Tue!L3 -> 46056
A5: Summary | B5: Tuesday | C5: Week to date | F5: Bars | G5: =SUM(G6:G9) -> 0
A6: Gaming Turnover | B6: =Takings!B25 -> 0 | C6: =SUM(Takings!B24:B25) -> 0 | F6: Public | G6: =Takings!C6 -> 0
A7: Gaming Gross | B7: =Takings!C25 -> 0 | C7: =SUM(Takings!C24:C25) -> 0 | F7: Bistro | G7: =Takings!D6 -> 0
A8: Gaming Net | B8: =Takings!I6 -> 0 | C8: =SUM(Takings!I5:I6) -> 0 | F8: Sports | G8: =Takings!E6 -> 0
A9: Dragon Link (50K) | F9: Taylors | G9: =Takings!F6 -> 0
A10: Dragon Train (20K)
A11: Fortune Hearts (25K)
A12: Dragon Rush (90K)
A13: Dragon Link (90K)
A14: Thunder Empire (50K) | F14: Bistro & Food Service
A15: Power Panther (12K) | F15: Day Covers | H15: Night Covers
A16: Bars | B16: =Takings!C46 -> 0 | C16: =SUM(Takings!B46:C46) -> 0 | F16: LUNCH Service Feedback
A17: Food | B17: =Takings!C49 -> 0 | C17: =SUM(Takings!B49:C49) -> 0
A18: Retail | B18: =Takings!H6 -> 0 | C18: =SUM(Takings!H5:H6) -> 0 | F18: Dinner Service Feedback
A19: TAB | B19: =Takings!L38 -> 0 | C19: =SUM(Takings!L37:L38) -> 0
F20: Public Bar
B21: DAY | C21: MID | D21: CLOSE | F21: Food | G21: =Tue!C22+Tue!C28 -> 0 | H21: Bev | I21: =Tue!J29 -> 0
A22: Managers Name | F22: Day
B23: GAMING
A24: Day turnover up to 6pm | B24: =G75 -> 0 | C24: Staff | F24: Evening
A25: How was the days trade
A26: Who were your big punters | F26: Late Night
A27: Large payouts/links & to whom
A28: Night turnover after 6pm | B28: =B6-B24 -> 0 | C28: Staff | F28: Bistro
A29: How was the night trade | F29: Food | G29: =Tue!C8 -> 0 | H29: Bev | I29: =Tue!J9 -> 0
A30: Who were your big punters | F30: Day
A31: Large payouts/links & to whom
B32: LINKS IF WON | F32: Evening
A33: What Link did they win
A34: How much was the Link | F34: Late Night
A35: What machine number
A36: How much were they betting | F36: Sports Bar
A37: Are they a regular | F37: Food | G37: =Tue!C15 -> 0 | H37: Bev | I37: =Tue!J16 -> 0
B38: AUSTRAC REPORTING | F38: Day
A39: Any Suspicious Customers
A40: Cash In to Turnover Ratio | B40: =Takings!B25/Takings!E25 -> #DIV/0! | F40: Evening
A41: Checked by
B42: TAB | F42: Late Night
...

Sheet Wed
A1: Republic Hotel - Daily Takings
A2: WEDNESDAY
K3: DATE: | L3: =Tue!L3+1 -> 46057 | N3: SUNDRIES | Q3: FOOD
A4: BISTRO | B4: READING | C4: FOOD | D4: TYRO FEE | E4: TIPS | F4: EXPECTED | G4: EFTPOS | H4: AMEX/DINER | I4: ME&U | J4: CASH | K4: VAR (+ / -) | L4: ACCOUNT | Q4: =A4 -> BISTRO | R4: =C8 -> 0
F5: =B5-(D5+L5) -> 0 | K5: =SUM(I5+J5+H5+G5)-F5 -> 0 | Q5: =A11 -> SPORTS BAR | R5: =C15 -> 0
F6: =B6-(D6+L6) -> 0 | K6: =SUM(I6+J6+H6+G6)-F6 -> 0 | Q6: BALCONY | R6: =C22+C28 -> 0
F7: =B7-(D7+L7) -> 0 | K7: =SUM(I7+J7+H7+G7)-F7 -> 0 | N7: TOTAL | O7: =O4+O5+O6 -> 0 | Q7: PUBLIC 1 / 2 | R7: =+C36+C42 -> 0
A8: TOTALS | B8: =SUM(B5:B7) -> 0 | C8: =SUM(C5:C7) -> 0 | D8: =SUM(D5:D7) -> 0 | E8: =SUM(E5:E7) -> 0 | F8: =SUM(F5:F7) -> 0 | G8: =SUM(G5:G7) -> 0 | H8: =SUM(H5:H7) -> 0 | I8: =SUM(I5:I7) -> 0 | J8: =SUM(J5:J7) -> 0 | K8: =SUM(I8+J8+H8+G8)-F8 -> 0 | L8: =SUM(L5:L7) -> 0 | Q8: BISTRO TILL | R8: =C57 -> 0
G9: BISTRO TOTAL | J9: =SUM(I8+J8+H8+G8)-C8-E8 -> 0 | Q9: TOTAL | R9: =SUM(R4:R8) -> 0
N10: TAB
A11: SPORTS BAR | B11: READING | C11: FOOD | D11: TYRO FEE | E11: TIPS | F11: EXPECTED | G11: EFTPOS | H11: AMEX/DINER | I11: ME&U | J11: CASH | K11: VAR (+ / -) | L11: ACCOUNT | N11: SALES | Q11: POKIES
F12: =B12-(D12+L12) -> 0 | K12: =SUM(I12+J12+H12+G12)-F12 -> 0 | N12: TERMINAL | Q12: CASH BOX
F13: =B13-(D13+L13) -> 0 | K13: =SUM(I13+J13+H13+G13)-F13 -> 0 | N13: EBET 1 | Q13: TICKET IN
F14: =B14-(D14+L14) -> 0 | K14: =SUM(I14+J14+H14+G14)-F14 -> 0 | N14: EBET 2 | Q14: CASH IN | R14: =R12-R13 -> 0
A15: TOTALS | B15: =SUM(B12:B14) -> 0 | C15: =SUM(C12:C14) -> 0 | D15: =SUM(D12:D14) -> 0 | E15: =SUM(E12:E14) -> 0 | F15: =SUM(F12:F14) -> 0 | G15: =SUM(G12:G14) -> 0 | H15: =SUM(H12:H14) -> 0 | I15: =SUM(I12:I14) -> 0 | ... L15: =SUM(L12:L14) -> 0 | N15: TOTAL | O15: =SUM(O12:O14) -> 0 | Q15: MONEY OUT
G16: SPORTS BAR TOTAL | J16: =SUM(I15+J15+H15+G15)-C15-E15 -> 0 | N16: LIABILITY | Q16: LINK AUTO
N17: TERMINAL | Q17: LINK MAN
A18: PUBLIC 1 | B18: READING | C18: FOOD | D18: TYRO FEE | E18: TIPS | F18: EXPECTED | G18: EFTPOS | H18: AMEX/DINER | I18: ME&U | J18: CASH | K18: VAR (+ / -) | L18: ACCOUNT | N18: EBET 1 | Q18: C/CREDITS
F19: =B19-(D19+L19) -> 0 | K19: =SUM(I19+J19+H19+G19)-F19 -> 0 | N19: EBET 2 | Q19: NET | R19: =R12-R15-R17-R18 -> 0
F20: =B20-(D20+L20) -> 0 | K20: =SUM(I20+J20+H20+G20)-F20 -> 0 | N20: TOTAL | O20: =SUM(O17:O19) -> 0 | Q20: TURNOVER
F21: =B21-(D21+L21) -> 0 | K21: =SUM(I21+J21+H21+G21)-F21 -> 0
A22: TOTALS | B22: =SUM(B19:B21) -> 0 | C22: =SUM(C19:C21) -> 0 | D22: =SUM(D19:D21) -> 0 | E22: =SUM(E19:E21) -> 0 | F22: =SUM(F19:F21) -> 0 | G22: =SUM(G19:G21) -> 0 | H22: =SUM(H19:H21) -> 0 | I22: =SUM(I19:I21) -> 0 | ... L22: =SUM(L19:L21) -> 0 | N22: EFTPOS
N23: =A11 -> SPORTS BAR | O23: =G15 -> 0 | Q23: TOTALS
A24: PUBLIC 2/GAMING | B24: READING | C24: FOOD | D24: TYRO FEE | E24: TIPS | F24: EXPECTED | G24: EFTPOS | H24: AMEX/DINER | I24: ME&U | J24: CASH | K24: VAR (+ / -) | L24: ACCOUNT | N24: =A4 -> BISTRO | O24: =G8 -> 0 | Q24: RECEIPTS | R24: =SUM(J29,J51,O7,J43,J16,J9,R19,J58,R9) -> 0
F25: =B25-(D25+L25) -> 0 | K25: =SUM(I25+J25+H25+G25)-F25 -> 0 | N25: B/SHOP | O25: =G50 -> 0 | Q25: GST | R25: =ROUND(+R24/11,2) -> 0
F26: =B26-(D26+L26) -> 0 | K26: =SUM(I26+J26+H26+G26)-F26 -> 0 | N26: PUBLIC 1 | O26: =G22 -> 0 | Q26: ATM | R26: =R39 -> 0
F27: =B27-(D27+L27) -> 0 | K27: =SUM(I27+J27+H27+G27)-F27 -> 0 | N27: PUBLIC 2 | O27: =G28 -> 0 | Q27: ME&U | R27: =I57+I42+I36+I28+I22+I15+I8 -> 0
A28: TOTALS | B28: =SUM(B25:B27) -> 0 | C28: =SUM(C25:C27) -> 0 | D28: =SUM(D25:D27) -> 0 | E28: =SUM(E25:E27) -> 0 | F28: =SUM(F25:F27) -> 0 | G28: =SUM(G25:G27) -> 0 | H28: =SUM(H25:H27) -> 0 | I28: =SUM(I25:I27) -> 0 | ... L28: =SUM(L25:L27) -> 0 | N28: ROOF TOP 1 | O28: =G36 -> 0 | Q28: EFTPOS | R28: =O31 -> 0
G29: PUBLIC BAR TOTAL | J29: =SUM(G22+H22+I22+J22)+(I28+J28+H28+G28)-C28-E28-C22-E22 -> 0 | N29: ROOF TOP 2 | O29: =G42 -> 0 | Q29: BANKING | R29: =R24-(R28+R26+R27) -> 0
N30: BISTRO | O30: =G57 -> 0
A31: TAYLORS BAR | N31: TOTAL | O31: =SUM(O23:O30) -> 0 | Q31: TAKING TIN | R31: =J8+J15+J22+J28+J36+J42+J50+J57 -> 0
A32: ROOF TOP 1 | B32: READING | C32: FOOD | D32: TYRO FEE | E32: TIPS | F32: EXPECTED | G32: EFTPOS | H32: AMEX/DINER | I32: ME&U | J32: CASH | K32: VAR (+ / -) | L32: ACCOUNT
F33: =B33-(D33+L33) -> 0 | K33: =SUM(I33+J33+H33+G33)-F33 -> 0 | Q33: TAB (ATM)
F34: =B34-(D34+L34) -> 0 | K34: =SUM(I34+J34+H34+G34)-F34 -> 0
F35: =B35-(D35+L35) -> 0 | K35: =SUM(I35+J35+H35+G35)-F35 -> 0
A36: TOTALS | B36: =SUM(B33:B35) -> 0 | C36: =SUM(C33:C35) -> 0 | D36: =SUM(D33:D35) -> 0 | E36: =SUM(E33:E35) -> 0 | F36: =SUM(F33:F35) -> 0 | G36: =SUM(G33:G35) -> 0 | H36: =SUM(H33:H35) -> 0 | I36: =SUM(I33:I35) -> 0 | ... L36: =SUM(L33:L35) -> 0 | Q36: ATM REFILL
Q37: ATM 1
A38: ROOF TOP 2 | B38: READING | C38: FOOD | D38: TYRO FEE | E38: TIPS | F38: EXPECTED | G38: EFTPOS | H38: AMEX/DINER | I38: ME&U | J38: CASH | K38: VAR (+ / -) | L38: ACCOUNT | Q38: ATM 2
F39: =B39-(D39+L39) -> 0 | K39: =SUM(I39+J39+H39+G39)-F39 -> 0 | Q39: TOTAL | R39: =SUM(R37:R38) -> 0
F40: =B40-(D40+L40) -> 0 | K40: =SUM(I40+J40+H40+G40)-F40 -> 0
...

Sheet Wed diary
A1: Republic Hotel
A2: =Wed!L3 -> 46057
A3: Weather -
A5: Summary | B5: Wednesday | C5: Week to date | F5: Bars | G5: =SUM(G6:G9) -> 0
A6: Gaming Turnover | B6: =Takings!B26 -> 0 | C6: =SUM(Takings!B24:B26) -> 0 | F6: Public | G6: =Takings!C7 -> 0
A7: Gaming Gross | B7: =Takings!C26 -> 0 | C7: =SUM(Takings!C24:C26) -> 0 | F7: Bistro | G7: =Takings!D7 -> 0
A8: Gaming Net | B8: =Takings!I7 -> 0 | C8: =SUM(Takings!I5:I7) -> 0 | F8: Sports | G8: =Takings!E7 -> 0
A9: Dragon Link (50K) | F9: Taylors | G9: =Takings!F7 -> 0
A10: Dragon Train (20K)
A11: Fortune Hearts (25K)
A12: Dragon Rush (90K)
A13: Dragon Link (90K)
A14: Thunder Empire (50K) | F14: Bistro & Food Service
A15: Power Panther (12K) | F15: Day Covers | H15: Night Covers
A16: Bars | B16: =Takings!D46 -> 0 | C16: =SUM(Takings!B46:D46) -> 0 | F16: LUNCH Service Feedback
A17: Food | B17: =Takings!D49 -> 0 | C17: =SUM(Takings!B49:D49) -> 0
A18: Retail | B18: =Takings!H7 -> 0 | C18: =SUM(Takings!H5:H7) -> 0 | F18: Dinner Service Feedback
A19: TAB | B19: =Takings!L39 -> 0 | C19: =SUM(Takings!L37:L39) -> 0
F20: Public Bar
B21: DAY | C21: MID | D21: CLOSE | F21: Food | G21: =Wed!C22+Wed!C28 -> 0 | H21: Bev | I21: =Wed!J29 -> 0
A22: Managers Name | F22: Day
B23: GAMING
A24: Day turnover up to 6pm | B24: =G75 -> 0 | C24: Staff | F24: Evening
A25: How was the days trade
A26: Who were your big punters | F26: Late Night
A27: Large payouts/links & to whom
A28: Night turnover after 6pm | B28: =B6-B24 -> 0 | C28: Staff | F28: Bistro
A29: How was the night trade | F29: Food | G29: =Wed!C8 -> 0 | H29: Bev | I29: =Wed!J9 -> 0
A30: Who were your big punters | F30: Day
A31: Large payouts/links & to whom
B32: LINKS IF WON | F32: Evening
A33: What Link did they win
A34: How much was the Link | F34: Late Night
A35: What machine number
A36: How much were they betting | F36: Sports Bar
A37: Are they a regular | F37: Food | G37: =Wed!C15 -> 0 | H37: Bev | I37: =Wed!J16 -> 0
B38: AUSTRAC REPORTING | F38: Day
A39: Any Suspicious Customers
A40: Cash In to Turnover Ratio | B40: =Takings!B26/Takings!E26 -> #DIV/0! | F40: Evening
A41: Checked by
...

Sheet Thu
A1: Republic Hotel - Daily Takings
A2: THURSDAY
K3: DATE: | L3: =Wed!L3+1 -> 46058 | N3: SUNDRIES | Q3: FOOD
A4: BISTRO | B4: READING | C4: FOOD | D4: TYRO FEE | E4: TIPS | F4: EXPECTED | G4: EFTPOS | H4: AMEX/DINER | I4: ME&U | J4: CASH | K4: VAR (+ / -) | L4: ACCOUNT | Q4: =A4 -> BISTRO | R4: =C8 -> 0
F5: =B5-(D5+L5) -> 0 | K5: =SUM(I5+J5+H5+G5)-F5 -> 0 | Q5: =A11 -> SPORTS BAR | R5: =C15 -> 0
F6: =B6-(D6+L6) -> 0 | K6: =SUM(I6+J6+H6+G6)-F6 -> 0 | Q6: BALCONY | R6: =C22+C28 -> 0
F7: =B7-(D7+L7) -> 0 | K7: =SUM(I7+J7+H7+G7)-F7 -> 0 | N7: TOTAL | O7: =O4+O5+O6 -> 0 | Q7: PUBLIC 1 / 2 | R7: =+C36+C42 -> 0
A8: TOTALS | B8: =SUM(B5:B7) -> 0 | C8: =SUM(C5:C7) -> 0 | D8: =SUM(D5:D7) -> 0 | E8: =SUM(E5:E7) -> 0 | F8: =SUM(F5:F7) -> 0 | G8: =SUM(G5:G7) -> 0 | H8: =SUM(H5:H7) -> 0 | I8: =SUM(I5:I7) -> 0 | J8: =SUM(J5:J7) -> 0 | K8: =SUM(I8+J8+H8+G8)-F8 -> 0 | L8: =SUM(L5:L7) -> 0 | Q8: BISTRO TILL | R8: =C57 -> 0
G9: BISTRO TOTAL | J9: =SUM(I8+J8+H8+G8)-C8-E8 -> 0 | Q9: TOTAL | R9: =SUM(R4:R8) -> 0
N10: TAB
A11: SPORTS BAR | B11: READING | C11: FOOD | D11: TYRO FEE | E11: TIPS | F11: EXPECTED | G11: EFTPOS | H11: AMEX/DINER | I11: ME&U | J11: CASH | K11: VAR (+ / -) | L11: ACCOUNT | N11: SALES | Q11: POKIES
F12: =B12-(D12+L12) -> 0 | K12: =SUM(I12+J12+H12+G12)-F12 -> 0 | N12: TERMINAL | Q12: CASH BOX
F13: =B13-(D13+L13) -> 0 | K13: =SUM(I13+J13+H13+G13)-F13 -> 0 | N13: EBET 1 | Q13: TICKET IN
F14: =B14-(D14+L14) -> 0 | K14: =SUM(I14+J14+H14+G14)-F14 -> 0 | N14: EBET 2 | Q14: CASH IN | R14: =R12-R13 -> 0
A15: TOTALS | B15: =SUM(B12:B14) -> 0 | C15: =SUM(C12:C14) -> 0 | D15: =SUM(D12:D14) -> 0 | E15: =SUM(E12:E14) -> 0 | F15: =SUM(F12:F14) -> 0 | G15: =SUM(G12:G14) -> 0 | H15: =SUM(H12:H14) -> 0 | I15: =SUM(I12:I14) -> 0 | ... L15: =SUM(L12:L14) -> 0 | N15: TOTAL | O15: =SUM(O12:O14) -> 0 | Q15: MONEY OUT
G16: SPORTS BAR TOTAL | J16: =SUM(I15+J15+H15+G15)-C15-E15 -> 0 | N16: LIABILITY | Q16: LINK AUTO
N17: TERMINAL | Q17: LINK MAN
A18: PUBLIC 1 | B18: READING | C18: FOOD | D18: TYRO FEE | E18: TIPS | F18: EXPECTED | G18: EFTPOS | H18: AMEX/DINER | I18: ME&U | J18: CASH | K18: VAR (+ / -) | L18: ACCOUNT | N18: EBET 1 | Q18: C/CREDITS
F19: =B19-(D19+L19) -> 0 | K19: =SUM(I19+J19+H19+G19)-F19 -> 0 | N19: EBET 2 | Q19: NET | R19: =R12-R15-R17-R18 -> 0
F20: =B20-(D20+L20) -> 0 | K20: =SUM(I20+J20+H20+G20)-F20 -> 0 | N20: TOTAL | O20: =SUM(O17:O19) -> 0 | Q20: TURNOVER
F21: =B21-(D21+L21) -> 0 | K21: =SUM(I21+J21+H21+G21)-F21 -> 0
A22: TOTALS | B22: =SUM(B19:B21) -> 0 | C22: =SUM(C19:C21) -> 0 | D22: =SUM(D19:D21) -> 0 | E22: =SUM(E19:E21) -> 0 | F22: =SUM(F19:F21) -> 0 | G22: =SUM(G19:G21) -> 0 | H22: =SUM(H19:H21) -> 0 | I22: =SUM(I19:I21) -> 0 | ... L22: =SUM(L19:L21) -> 0 | N22: EFTPOS
N23: =A11 -> SPORTS BAR | O23: =G15 -> 0 | Q23: TOTALS
A24: PUBLIC 2/GAMING | B24: READING | C24: FOOD | D24: TYRO FEE | E24: TIPS | F24: EXPECTED | G24: EFTPOS | H24: AMEX/DINER | I24: ME&U | J24: CASH | K24: VAR (+ / -) | L24: ACCOUNT | N24: =A4 -> BISTRO | O24: =G8 -> 0 | Q24: RECEIPTS | R24: =SUM(J29,J51,O7,J43,J16,J9,R19,J58,R9) -> 0
F25: =B25-(D25+L25) -> 0 | K25: =SUM(I25+J25+H25+G25)-F25 -> 0 | N25: B/SHOP | O25: =G50 -> 0 | Q25: GST | R25: =ROUND(+R24/11,2) -> 0
F26: =B26-(D26+L26) -> 0 | K26: =SUM(I26+J26+H26+G26)-F26 -> 0 | N26: PUBLIC 1 | O26: =G22 -> 0 | Q26: ATM | R26: =R39 -> 0
F27: =B27-(D27+L27) -> 0 | K27: =SUM(I27+J27+H27+G27)-F27 -> 0 | N27: PUBLIC 2 | O27: =G28 -> 0 | Q27: ME&U | R27: =I57+I42+I36+I28+I22+I15+I8 -> 0
A28: TOTALS | B28: =SUM(B25:B27) -> 0 | C28: =SUM(C25:C27) -> 0 | D28: =SUM(D25:D27) -> 0 | E28: =SUM(E25:E27) -> 0 | F28: =SUM(F25:F27) -> 0 | G28: =SUM(G25:G27) -> 0 | H28: =SUM(H25:H27) -> 0 | I28: =SUM(I25:I27) -> 0 | ... L28: =SUM(L25:L27) -> 0 | N28: ROOF TOP 1 | O28: =G36 -> 0 | Q28: EFTPOS | R28: =O31 -> 0
G29: PUBLIC BAR TOTAL | J29: =SUM(G22+H22+I22+J22)+(I28+J28+H28+G28)-C28-E28-C22-E22 -> 0 | N29: ROOF TOP 2 | O29: =G42 -> 0 | Q29: BANKING | R29: =R24-(R28+R26+R27) -> 0
N30: BISTRO | O30: =G57 -> 0
A31: TAYLORS BAR | N31: TOTAL | O31: =SUM(O23:O30) -> 0 | Q31: TAKING TIN | R31: =J8+J15+J22+J28+J36+J42+J50+J57 -> 0
A32: ROOF TOP 1 | B32: READING | C32: FOOD | D32: TYRO FEE | E32: TIPS | F32: EXPECTED | G32: EFTPOS | H32: AMEX/DINER | I32: ME&U | J32: CASH | K32: VAR (+ / -) | L32: ACCOUNT
F33: =B33-(D33+L33) -> 0 | K33: =SUM(I33+J33+H33+G33)-F33 -> 0 | Q33: TAB (ATM)
F34: =B34-(D34+L34) -> 0 | K34: =SUM(I34+J34+H34+G34)-F34 -> 0
F35: =B35-(D35+L35) -> 0 | K35: =SUM(I35+J35+H35+G35)-F35 -> 0
A36: TOTALS | B36: =SUM(B33:B35) -> 0 | C36: =SUM(C33:C35) -> 0 | D36: =SUM(D33:D35) -> 0 | E36: =SUM(E33:E35) -> 0 | F36: =SUM(F33:F35) -> 0 | G36: =SUM(G33:G35) -> 0 | H36: =SUM(H33:H35) -> 0 | I36: =SUM(I33:I35) -> 0 | ... L36: =SUM(L33:L35) -> 0 | Q36: ATM REFILL
Q37: ATM 1
A38: ROOF TOP 2 | B38: READING | C38: FOOD | D38: TYRO FEE | E38: TIPS | F38: EXPECTED | G38: EFTPOS | H38: AMEX/DINER | I38: ME&U | J38: CASH | K38: VAR (+ / -) | L38: ACCOUNT | Q38: ATM 2
F39: =B39-(D39+L39) -> 0 | K39: =SUM(I39+J39+H39+G39)-F39 -> 0 | Q39: TOTAL | R39: =SUM(R37:R38) -> 0
F40: =B40-(D40+L40) -> 0 | K40: =SUM(I40+J40+H40+G40)-F40 -> 0
...

Sheet Thu diary
A1: Republic Hotel
A2: =Thu!L3 -> 46058
A3: Weather -
A5: Summary | B5: Thursday | C5: Week to date | F5: Bars | G5: =SUM(G6:G9) -> 0
A6: Gaming Turnover | B6: =Takings!B27 -> 0 | C6: =SUM(Takings!B24:B27) -> 0 | F6: Public | G6: =Takings!C8 -> 0
A7: Gaming Gross | B7: =Takings!C27 -> 0 | C7: =SUM(Takings!C24:C27) -> 0 | F7: Bistro | G7: =Takings!D8 -> 0
A8: Gaming Net | B8: =Takings!I8 -> 0 | C8: =SUM(Takings!I5:I8) -> 0 | F8: Sports | G8: =Takings!E8 -> 0
A9: Dragon Link (50K) | F9: Taylors | G9: =Takings!F8 -> 0
A10: Dragon Train (20K)
A11: Fortune Hearts (25K)
A12: Dragon Rush (90K)
A13: Dragon Link (90K)
A14: Thunder Empire (50K) | F14: Bistro & Food Service
A15: Power Panther (12K) | F15: Day Covers | H15: Night Covers
A16: Bars | B16: =Takings!E46 -> 0 | C16: =SUM(Takings!B46:E46) -> 0 | F16: LUNCH Service Feedback
A17: Food | B17: =Takings!E49 -> 0 | C17: =SUM(Takings!B49:E49) -> 0
A18: Retail | B18: =Takings!H8 -> 0 | C18: =SUM(Takings!H5:H8) -> 0 | F18: Dinner Service Feedback
A19: TAB | B19: =Takings!L40 -> 0 | C19: =SUM(Takings!L37:L40) -> 0
F20: Public Bar
B21: DAY | C21: MID | D21: CLOSE | F21: Food | G21: =Thu!C22+Thu!C28 -> 0 | H21: Bev | I21: =Thu!J29 -> 0
A22: Managers Name | F22: Day
B23: GAMING
A24: Day turnover up to 6pm | B24: =G75 -> 0 | C24: Staff | F24: Evening
A25: How was the days trade
A26: Who were your big punters | F26: Late Night
A27: Large payouts/links & to whom
A28: Night turnover after 6pm | B28: =B6-B24 -> 0 | C28: Staff | F28: Bistro
A29: How was the night trade | F29: Food | G29: =Thu!C8 -> 0 | H29: Bev | I29: =Thu!J9 -> 0
A30: Who were your big punters | F30: Day
A31: Large payouts/links & to whom
B32: LINKS IF WON | F32: Evening
A33: What Link did they win
A34: How much was the Link | F34: Late Night
A35: What machine number
A36: How much were they betting | F36: Sports Bar
A37: Are they a regular | F37: Food | G37: =Thu!C15 -> 0 | H37: Bev | I37: =Thu!J16 -> 0
B38: AUSTRAC REPORTING | F38: Day
A39: Any Suspicious Customers
A40: Cash In to Turnover Ratio | B40: =Takings!B27/Takings!E27 -> #DIV/0! | F40: Evening
A41: Checked by
...

Sheet Fri
A1: Republic Hotel - Daily Takings
A2: FRIDAY
K3: DATE: | L3: =Thu!L3+1 -> 46059 | N3: SUNDRIES | Q3: FOOD
A4: BISTRO | B4: READING | C4: FOOD | D4: TYRO FEE | E4: TIPS | F4: EXPECTED | G4: EFTPOS | H4: AMEX/DINER | I4: ME&U | J4: CASH | K4: VAR (+ / -) | L4: ACCOUNT | Q4: =A4 -> BISTRO | R4: =C8 -> 0
F5: =B5-(D5+L5) -> 0 | K5: =SUM(I5+J5+H5+G5)-F5 -> 0 | Q5: =A11 -> SPORTS BAR | R5: =C15 -> 0
F6: =B6-(D6+L6) -> 0 | K6: =SUM(I6+J6+H6+G6)-F6 -> 0 | Q6: BALCONY | R6: =C22+C28 -> 0
F7: =B7-(D7+L7) -> 0 | K7: =SUM(I7+J7+H7+G7)-F7 -> 0 | N7: TOTAL | O7: =O4+O5+O6 -> 0 | Q7: PUBLIC 1 / 2 | R7: =+C36+C42 -> 0
A8: TOTALS | B8: =SUM(B5:B7) -> 0 | C8: =SUM(C5:C7) -> 0 | D8: =SUM(D5:D7) -> 0 | E8: =SUM(E5:E7) -> 0 | F8: =SUM(F5:F7) -> 0 | G8: =SUM(G5:G7) -> 0 | H8: =SUM(H5:H7) -> 0 | I8: =SUM(I5:I7) -> 0 | J8: =SUM(J5:J7) -> 0 | K8: =SUM(I8+J8+H8+G8)-F8 -> 0 | L8: =SUM(L5:L7) -> 0 | Q8: BISTRO TILL | R8: =C57 -> 0
G9: BISTRO TOTAL | J9: =SUM(I8+J8+H8+G8)-C8-E8 -> 0 | Q9: TOTAL | R9: =SUM(R4:R8) -> 0
N10: TAB
A11: SPORTS BAR | B11: READING | C11: FOOD | D11: TYRO FEE | E11: TIPS | F11: EXPECTED | G11: EFTPOS | H11: AMEX/DINER | I11: ME&U | J11: CASH | K11: VAR (+ / -) | L11: ACCOUNT | N11: SALES | Q11: POKIES
F12: =B12-(D12+L12) -> 0 | K12: =SUM(I12+J12+H12+G12)-F12 -> 0 | N12: TERMINAL | Q12: CASH BOX
F13: =B13-(D13+L13) -> 0 | K13: =SUM(I13+J13+H13+G13)-F13 -> 0 | N13: EBET 1 | Q13: TICKET IN
F14: =B14-(D14+L14) -> 0 | K14: =SUM(I14+J14+H14+G14)-F14 -> 0 | N14: EBET 2 | Q14: CASH IN | R14: =R12-R13 -> 0
A15: TOTALS | B15: =SUM(B12:B14) -> 0 | C15: =SUM(C12:C14) -> 0 | D15: =SUM(D12:D14) -> 0 | E15: =SUM(E12:E14) -> 0 | F15: =SUM(F12:F14) -> 0 | G15: =SUM(G12:G14) -> 0 | H15: =SUM(H12:H14) -> 0 | I15: =SUM(I12:I14) -> 0 | ... L15: =SUM(L12:L14) -> 0 | N15: TOTAL | O15: =SUM(O12:O14) -> 0 | Q15: MONEY OUT
G16: SPORTS BAR TOTAL | J16: =SUM(I15+J15+H15+G15)-C15-E15 -> 0 | N16: LIABILITY | Q16: LINK AUTO
N17: TERMINAL | Q17: LINK MAN
A18: PUBLIC 1 | B18: READING | C18: FOOD | D18: TYRO FEE | E18: TIPS | F18: EXPECTED | G18: EFTPOS | H18: AMEX/DINER | I18: ME&U | J18: CASH | K18: VAR (+ / -) | L18: ACCOUNT | N18: EBET 1 | Q18: C/CREDITS
F19: =B19-(D19+L19) -> 0 | K19: =SUM(I19+J19+H19+G19)-F19 -> 0 | N19: EBET 2 | Q19: NET | R19: =R12-R15-R17-R18 -> 0
F20: =B20-(D20+L20) -> 0 | K20: =SUM(I20+J20+H20+G20)-F20 -> 0 | N20: TOTAL | O20: =SUM(O17:O19) -> 0 | Q20: TURNOVER
F21: =B21-(D21+L21) -> 0 | K21: =SUM(I21+J21+H21+G21)-F21 -> 0
A22: TOTALS | B22: =SUM(B19:B21) -> 0 | C22: =SUM(C19:C21) -> 0 | D22: =SUM(D19:D21) -> 0 | E22: =SUM(E19:E21) -> 0 | F22: =SUM(F19:F21) -> 0 | G22: =SUM(G19:G21) -> 0 | H22: =SUM(H19:H21) -> 0 | I22: =SUM(I19:I21) -> 0 | ... L22: =SUM(L19:L21) -> 0 | N22: EFTPOS
N23: =A11 -> SPORTS BAR | O23: =G15 -> 0 | Q23: TOTALS
A24: PUBLIC 2/GAMING | B24: READING | C24: FOOD | D24: TYRO FEE | E24: TIPS | F24: EXPECTED | G24: EFTPOS | H24: AMEX/DINER | I24: ME&U | J24: CASH | K24: VAR (+ / -) | L24: ACCOUNT | N24: =A4 -> BISTRO | O24: =G8 -> 0 | Q24: RECEIPTS | R24: =SUM(J29,J51,O7,J43,J16,J9,R19,J58,R9) -> 0
F25: =B25-(D25+L25) -> 0 | K25: =SUM(I25+J25+H25+G25)-F25 -> 0 | N25: B/SHOP | O25: =G50 -> 0 | Q25: GST | R25: =ROUND(+R24/11,2) -> 0
F26: =B26-(D26+L26) -> 0 | K26: =SUM(I26+J26+H26+G26)-F26 -> 0 | N26: PUBLIC 1 | O26: =G22 -> 0 | Q26: ATM | R26: =R39 -> 0
F27: =B27-(D27+L27) -> 0 | K27: =SUM(I27+J27+H27+G27)-F27 -> 0 | N27: PUBLIC 2 | O27: =G28 -> 0 | Q27: ME&U | R27: =I57+I42+I36+I28+I22+I15+I8 -> 0
A28: TOTALS | B28: =SUM(B25:B27) -> 0 | C28: =SUM(C25:C27) -> 0 | D28: =SUM(D25:D27) -> 0 | E28: =SUM(E25:E27) -> 0 | F28: =SUM(F25:F27) -> 0 | G28: =SUM(G25:G27) -> 0 | H28: =SUM(H25:H27) -> 0 | I28: =SUM(I25:I27) -> 0 | ... L28: =SUM(L25:L27) -> 0 | N28: ROOF TOP 1 | O28: =G36 -> 0 | Q28: EFTPOS | R28: =O31 -> 0
G29: PUBLIC BAR TOTAL | J29: =SUM(G22+H22+I22+J22)+(I28+J28+H28+G28)-C28-E28-C22-E22 -> 0 | N29: ROOF TOP 2 | O29: =G42 -> 0 | Q29: BANKING | R29: =R24-(R28+R26+R27) -> 0
N30: BISTRO | O30: =G57 -> 0
A31: TAYLORS BAR | N31: TOTAL | O31: =SUM(O23:O30) -> 0 | Q31: TAKING TIN | R31: =J8+J15+J22+J28+J36+J42+J50+J57 -> 0
A32: ROOF TOP 1 | B32: READING | C32: FOOD | D32: TYRO FEE | E32: TIPS | F32: EXPECTED | G32: EFTPOS | H32: AMEX/DINER | I32: ME&U | J32: CASH | K32: VAR (+ / -) | L32: ACCOUNT
F33: =B33-(D33+L33) -> 0 | K33: =SUM(I33+J33+H33+G33)-F33 -> 0 | Q33: TAB (ATM)
F34: =B34-(D34+L34) -> 0 | K34: =SUM(I34+J34+H34+G34)-F34 -> 0
F35: =B35-(D35+L35) -> 0 | K35: =SUM(I35+J35+H35+G35)-F35 -> 0
A36: TOTALS | B36: =SUM(B33:B35) -> 0 | C36: =SUM(C33:C35) -> 0 | D36: =SUM(D33:D35) -> 0 | E36: =SUM(E33:E35) -> 0 | F36: =SUM(F33:F35) -> 0 | G36: =SUM(G33:G35) -> 0 | H36: =SUM(H33:H35) -> 0 | I36: =SUM(I33:I35) -> 0 | ... L36: =SUM(L33:L35) -> 0 | Q36: ATM REFILL
Q37: ATM 1
A38: ROOF TOP 2 | B38: READING | C38: FOOD | D38: TYRO FEE | E38: TIPS | F38: EXPECTED | G38: EFTPOS | H38: AMEX/DINER | I38: ME&U | J38: CASH | K38: VAR (+ / -) | L38: ACCOUNT | Q38: ATM 2
F39: =B39-(D39+L39) -> 0 | K39: =SUM(I39+J39+H39+G39)-F39 -> 0 | Q39: TOTAL | R39: =SUM(R37:R38) -> 0
F40: =B40-(D40+L40) -> 0 | K40: =SUM(I40+J40+H40+G40)-F40 -> 0
...

Sheet Fri diary
A1: Republic Hotel
A2: =Fri!L3 -> 46059
A3: Weather -
A5: Summary | B5: Friday | C5: Week to date | F5: Bars | G5: =SUM(G6:G9) -> 0
A6: Gaming Turnover | B6: =Takings!B28 -> 0 | C6: =SUM(Takings!B24:B28) -> 0 | F6: Public | G6: =Takings!C9 -> 0
A7: Gaming Gross | B7: =Takings!C28 -> 0 | C7: =SUM(Takings!C24:C28) -> 0 | F7: Bistro | G7: =Takings!D9 -> 0
A8: Gaming Net | B8: =Takings!I9 -> 0 | C8: =SUM(Takings!I5:I9) -> 0 | F8: Sports | G8: =Takings!E9 -> 0
A9: Dragon Link (50K) | F9: Taylors | G9: =Takings!F9 -> 0
A10: Dragon Train (20K)
A11: Fortune Hearts (25K)
A12: Dragon Rush (90K)
A13: Dragon Link (90K)
A14: Thunder Empire (50K) | F14: Bistro & Food Service
A15: Power Panther (12K) | F15: Day Covers | H15: Night Covers
A16: Bars | B16: =Takings!F46 -> 0 | C16: =SUM(Takings!B46:F46) -> 0 | F16: LUNCH Service Feedback
A17: Food | B17: =Takings!F49 -> 0 | C17: =SUM(Takings!B49:F49) -> 0
A18: Retail | B18: =Takings!H9 -> 0 | C18: =SUM(Takings!H5:H9) -> 0 | F18: Dinner Service Feedback
A19: TAB | B19: =Takings!L41 -> 0 | C19: =SUM(Takings!L37:L41) -> 0
F20: Public Bar
B21: DAY | C21: MID | D21: CLOSE | F21: Food | G21: =Fri!C22+Fri!C28 -> 0 | H21: Bev | I21: =Fri!J29 -> 0
A22: Managers Name | F22: Day
B23: GAMING
A24: Day turnover up to 6pm | B24: =G75 -> 0 | C24: Staff | F24: Evening
A25: How was the days trade
A26: Who were your big punters | F26: Late Night
A27: Large payouts/links & to whom
A28: Night turnover after 6pm | B28: =B6-B24 -> 0 | C28: Staff | F28: Bistro
A29: How was the night trade | F29: Food | G29: =Fri!C8 -> 0 | H29: Bev | I29: =Fri!J9 -> 0
A30: Who were your big punters | F30: Day
A31: Large payouts/links & to whom
B32: LINKS IF WON | F32: Evening
A33: What Link did they win
A34: How much was the Link | F34: Late Night
A35: What machine number
A36: How much were they betting | F36: Sports Bar
A37: Are they a regular | F37: Food | G37: =Fri!C15 -> 0 | H37: Bev | I37: =Fri!J16 -> 0
B38: AUSTRAC REPORTING | F38: Day
A39: Any Suspicious Customers
A40: Cash In to Turnover Ratio | B40: =Takings!B28/Takings!E28 -> #DIV/0! | F40: Evening
A41: Checked by
...

Sheet Sat
A1: Republic Hotel - Daily Takings
A2: SATURDAY
K3: DATE: | L3: =Fri!L3+1 -> 46060 | N3: SUNDRIES | Q3: FOOD
A4: BISTRO | B4: READING | C4: FOOD | D4: TYRO FEE | E4: TIPS | F4: EXPECTED | G4: EFTPOS | H4: AMEX/DINER | I4: ME&U | J4: CASH | K4: VAR (+ / -) | L4: ACCOUNT | Q4: =A4 -> BISTRO | R4: =C8 -> 0
F5: =B5-(D5+L5) -> 0 | K5: =SUM(I5+J5+H5+G5)-F5 -> 0 | Q5: =A11 -> SPORTS BAR | R5: =C15 -> 0
F6: =B6-(D6+L6) -> 0 | K6: =SUM(I6+J6+H6+G6)-F6 -> 0 | Q6: BALCONY | R6: =C22+C28 -> 0
F7: =B7-(D7+L7) -> 0 | K7: =SUM(I7+J7+H7+G7)-F7 -> 0 | N7: TOTAL | O7: =O4+O5+O6 -> 0 | Q7: PUBLIC 1 / 2 | R7: =+C36+C42 -> 0
A8: TOTALS | B8: =SUM(B5:B7) -> 0 | C8: =SUM(C5:C7) -> 0 | D8: =SUM(D5:D7) -> 0 | E8: =SUM(E5:E7) -> 0 | F8: =SUM(F5:F7) -> 0 | G8: =SUM(G5:G7) -> 0 | H8: =SUM(H5:H7) -> 0 | I8: =SUM(I5:I7) -> 0 | J8: =SUM(J5:J7) -> 0 | K8: =SUM(I8+J8+H8+G8)-F8 -> 0 | L8: =SUM(L5:L7) -> 0 | Q8: BISTRO TILL | R8: =C57 -> 0
G9: BISTRO TOTAL | J9: =SUM(I8+J8+H8+G8)-C8-E8 -> 0 | Q9: TOTAL | R9: =SUM(R4:R8) -> 0
N10: TAB
A11: SPORTS BAR | B11: READING | C11: FOOD | D11: TYRO FEE | E11: TIPS | F11: EXPECTED | G11: EFTPOS | H11: AMEX/DINER | I11: ME&U | J11: CASH | K11: VAR (+ / -) | L11: ACCOUNT | N11: SALES | Q11: POKIES
F12: =B12-(D12+L12) -> 0 | K12: =SUM(I12+J12+H12+G12)-F12 -> 0 | N12: TERMINAL | Q12: CASH BOX
F13: =B13-(D13+L13) -> 0 | K13: =SUM(I13+J13+H13+G13)-F13 -> 0 | N13: EBET 1 | Q13: TICKET IN
F14: =B14-(D14+L14) -> 0 | K14: =SUM(I14+J14+H14+G14)-F14 -> 0 | N14: EBET 2 | Q14: CASH IN | R14: =R12-R13 -> 0
A15: TOTALS | B15: =SUM(B12:B14) -> 0 | C15: =SUM(C12:C14) -> 0 | D15: =SUM(D12:D14) -> 0 | E15: =SUM(E12:E14) -> 0 | F15: =SUM(F12:F14) -> 0 | G15: =SUM(G12:G14) -> 0 | H15: =SUM(H12:H14) -> 0 | I15: =SUM(I12:I14) -> 0 | ... L15: =SUM(L12:L14) -> 0 | N15: TOTAL | O15: =SUM(O12:O14) -> 0 | Q15: MONEY OUT
G16: SPORTS BAR TOTAL | J16: =SUM(I15+J15+H15+G15)-C15-E15 -> 0 | N16: LIABILITY | Q16: LINK AUTO
N17: TERMINAL | Q17: LINK MAN
A18: PUBLIC 1 | B18: READING | C18: FOOD | D18: TYRO FEE | E18: TIPS | F18: EXPECTED | G18: EFTPOS | H18: AMEX/DINER | I18: ME&U | J18: CASH | K18: VAR (+ / -) | L18: ACCOUNT | N18: EBET 1 | Q18: C/CREDITS
F19: =B19-(D19+L19) -> 0 | K19: =SUM(I19+J19+H19+G19)-F19 -> 0 | N19: EBET 2 | Q19: NET | R19: =R12-R15-R17-R18 -> 0
F20: =B20-(D20+L20) -> 0 | K20: =SUM(I20+J20+H20+G20)-F20 -> 0 | N20: TOTAL | O20: =SUM(O17:O19) -> 0 | Q20: TURNOVER
F21: =B21-(D21+L21) -> 0 | K21: =SUM(I21+J21+H21+G21)-F21 -> 0
A22: TOTALS | B22: =SUM(B19:B21) -> 0 | C22: =SUM(C19:C21) -> 0 | D22: =SUM(D19:D21) -> 0 | E22: =SUM(E19:E21) -> 0 | F22: =SUM(F19:F21) -> 0 | G22: =SUM(G19:G21) -> 0 | H22: =SUM(H19:H21) -> 0 | I22: =SUM(I19:I21) -> 0 | ... L22: =SUM(L19:L21) -> 0 | N22: EFTPOS
N23: =A11 -> SPORTS BAR | O23: =G15 -> 0 | Q23: TOTALS
A24: PUBLIC 2/GAMING | B24: READING | C24: FOOD | D24: TYRO FEE | E24: TIPS | F24: EXPECTED | G24: EFTPOS | H24: AMEX/DINER | I24: ME&U | J24: CASH | K24: VAR (+ / -) | L24: ACCOUNT | N24: =A4 -> BISTRO | O24: =G8 -> 0 | Q24: RECEIPTS | R24: =SUM(J29,J51,O7,J43,J16,J9,R19,J58,R9) -> 0
F25: =B25-(D25+L25) -> 0 | K25: =SUM(I25+J25+H25+G25)-F25 -> 0 | N25: B/SHOP | O25: =G50 -> 0 | Q25: GST | R25: =ROUND(+R24/11,2) -> 0
F26: =B26-(D26+L26) -> 0 | K26: =SUM(I26+J26+H26+G26)-F26 -> 0 | N26: PUBLIC 1 | O26: =G22 -> 0 | Q26: ATM | R26: =R39 -> 0
F27: =B27-(D27+L27) -> 0 | K27: =SUM(I27+J27+H27+G27)-F27 -> 0 | N27: PUBLIC 2 | O27: =G28 -> 0 | Q27: ME&U | R27: =I57+I42+I36+I28+I22+I15+I8 -> 0
A28: TOTALS | B28: =SUM(B25:B27) -> 0 | C28: =SUM(C25:C27) -> 0 | D28: =SUM(D25:D27) -> 0 | E28: =SUM(E25:E27) -> 0 | F28: =SUM(F25:F27) -> 0 | G28: =SUM(G25:G27) -> 0 | H28: =SUM(H25:H27) -> 0 | I28: =SUM(I25:I27) -> 0 | ... L28: =SUM(L25:L27) -> 0 | N28: ROOF TOP 1 | O28: =G36 -> 0 | Q28: EFTPOS | R28: =O31 -> 0
G29: PUBLIC BAR TOTAL | J29: =SUM(G22+H22+I22+J22)+(I28+J28+H28+G28)-C28-E28-C22-E22 -> 0 | N29: ROOF TOP 2 | O29: =G42 -> 0 | Q29: BANKING | R29: =R24-(R28+R26+R27) -> 0
N30: BISTRO | O30: =G57 -> 0
A31: TAYLORS BAR | N31: TOTAL | O31: =SUM(O23:O30) -> 0 | Q31: TAKING TIN | R31: =J8+J15+J22+J28+J36+J42+J50+J57 -> 0
A32: ROOF TOP 1 | B32: READING | C32: FOOD | D32: TYRO FEE | E32: TIPS | F32: EXPECTED | G32: EFTPOS | H32: AMEX/DINER | I32: ME&U | J32: CASH | K32: VAR (+ / -) | L32: ACCOUNT
F33: =B33-(D33+L33) -> 0 | K33: =SUM(I33+J33+H33+G33)-F33 -> 0 | Q33: TAB (ATM)
F34: =B34-(D34+L34) -> 0 | K34: =SUM(I34+J34+H34+G34)-F34 -> 0
F35: =B35-(D35+L35) -> 0 | K35: =SUM(I35+J35+H35+G35)-F35 -> 0
A36: TOTALS | B36: =SUM(B33:B35) -> 0 | C36: =SUM(C33:C35) -> 0 | D36: =SUM(D33:D35) -> 0 | E36: =SUM(E33:E35) -> 0 | F36: =SUM(F33:F35) -> 0 | G36: =SUM(G33:G35) -> 0 | H36: =SUM(H33:H35) -> 0 | I36: =SUM(I33:I35) -> 0 | ... L36: =SUM(L33:L35) -> 0 | Q36: ATM REFILL
Q37: ATM 1
A38: ROOF TOP 2 | B38: READING | C38: FOOD | D38: TYRO FEE | E38: TIPS | F38: EXPECTED | G38: EFTPOS | H38: AMEX/DINER | I38: ME&U | J38: CASH | K38: VAR (+ / -) | L38: ACCOUNT | Q38: ATM 2
F39: =B39-(D39+L39) -> 0 | K39: =SUM(I39+J39+H39+G39)-F39 -> 0 | Q39: TOTAL | R39: =SUM(R37:R38) -> 0
F40: =B40-(D40+L40) -> 0 | K40: =SUM(I40+J40+H40+G40)-F40 -> 0
...

Sheet Sat diary
A1: Republic Hotel
A2: =Sat!L3 -> 46060
A5: Summary | B5: Saturday | C5: Week to date | F5: Bars | G5: =SUM(G6:G9) -> 0
A6: Gaming Turnover | B6: =Takings!B29 -> 0 | C6: =SUM(Takings!B24:B29) -> 0 | F6: Public | G6: =Takings!C10 -> 0
A7: Gaming Gross | B7: =Takings!C29 -> 0 | C7: =SUM(Takings!C24:C29) -> 0 | F7: Bistro | G7: =Takings!D10 -> 0
A8: Gaming Net | B8: =Takings!I10 -> 0 | C8: =SUM(Takings!I5:I10) -> 0 | F8: Sports | G8: =Takings!E10 -> 0
A9: Dragon Link (50K) | F9: Taylors | G9: =Takings!F10 -> 0
A10: Dragon Train (20K)
A11: Fortune Hearts (25K)
A12: Dragon Rush (90K)
A13: Dragon Link (90K)
A14: Thunder Empire (50K) | F14: Bistro & Food Service
A15: Power Panther (12K) | F15: Day Covers | H15: Night Covers
A16: Bars | B16: =Takings!G46 -> 0 | C16: =SUM(Takings!B46:G46) -> 0 | F16: LUNCH Service Feedback
A17: Food | B17: =Takings!G49 -> 0 | C17: =SUM(Takings!B49:G49) -> 0
A18: Retail | B18: =Takings!H10 -> 0 | C18: =SUM(Takings!H5:H10) -> 0 | F18: Dinner Service Feedback
A19: TAB | B19: =Takings!L42 -> 0 | C19: =SUM(Takings!L37:L42) -> 0
F20: Public Bar
B21: DAY | C21: MID | D21: CLOSE | F21: Food | G21: =Sat!C22+Sat!C28 -> 0 | H21: Bev | I21: =Sat!J29 -> 0
A22: Managers Name | F22: Day
B23: GAMING
A24: Day turnover up to 6pm | B24: =G75 -> 0 | C24: Staff | F24: Evening
A25: How was the days trade
A26: Who were your big punters | F26: Late Night
A27: Large payouts/links & to whom
A28: Night turnover after 6pm | B28: =B6-B24 -> 0 | C28: Staff | F28: Bistro
A29: How was the night trade | F29: Food | G29: =Sat!C8 -> 0 | H29: Bev | I29: =Sat!J9 -> 0
A30: Who were your big punters | F30: Day
A31: Large payouts/links & to whom
B32: LINKS IF WON | F32: Evening
A33: What Link did they win
A34: How much was the Link | F34: Late Night
A35: What machine number
A36: How much were they betting | F36: Sports Bar
A37: Are they a regular | F37: Food | G37: =Sat!C15 -> 0 | H37: Bev | I37: =Sat!J16 -> 0
B38: AUSTRAC REPORTING | F38: Day
A39: Any Suspicious Customers
A40: Cash In to Turnover Ratio | B40: =Takings!B29/Takings!E29 -> #DIV/0! | F40: Evening
A41: Checked by
B42: TAB | F42: Late Night
...

Sheet Sun
A1: Republic Hotel - Daily Takings
A2: SUNDAY
K3: DATE: | L3: =Sat!L3+1 -> 46061 | N3: SUNDRIES | Q3: FOOD
A4: BISTRO | B4: READING | C4: FOOD | D4: TYRO FEE | E4: TIPS | F4: EXPECTED | G4: EFTPOS | H4: AMEX/DINER | I4: ME&U | J4: CASH | K4: VAR (+ / -) | L4: ACCOUNT | N4: TAB COMM | O4: =Takings!M45 -> 0 | Q4: =A4 -> BISTRO | R4: =C8 -> 0
F5: =B5-(D5+L5) -> 0 | K5: =SUM(I5+J5+H5+G5)-F5 -> 0 | Q5: =A11 -> SPORTS BAR | R5: =C15 -> 0
F6: =B6-(D6+L6) -> 0 | K6: =SUM(I6+J6+H6+G6)-F6 -> 0 | Q6: BALCONY | R6: =C22+C28 -> 0
F7: =B7-(D7+L7) -> 0 | K7: =SUM(I7+J7+H7+G7)-F7 -> 0 | N7: TOTAL | O7: =O4+O5+O6 -> 0 | Q7: PUBLIC 1 / 2 | R7: =+C36+C42 -> 0
A8: TOTALS | B8: =SUM(B5:B7) -> 0 | C8: =SUM(C5:C7) -> 0 | D8: =SUM(D5:D7) -> 0 | E8: =SUM(E5:E7) -> 0 | F8: =SUM(F5:F7) -> 0 | G8: =SUM(G5:G7) -> 0 | H8: =SUM(H5:H7) -> 0 | I8: =SUM(I5:I7) -> 0 | J8: =SUM(J5:J7) -> 0 | K8: =SUM(I8+J8+H8+G8)-F8 -> 0 | L8: =SUM(L5:L7) -> 0 | Q8: BISTRO TILL | R8: =C57 -> 0
G9: BISTRO TOTAL | J9: =SUM(I8+J8+H8+G8)-C8-E8 -> 0 | Q9: TOTAL | R9: =SUM(R4:R8) -> 0
N10: TAB
A11: SPORTS BAR | B11: READING | C11: FOOD | D11: TYRO FEE | E11: TIPS | F11: EXPECTED | G11: EFTPOS | H11: AMEX/DINER | I11: ME&U | J11: CASH | K11: VAR (+ / -) | L11: ACCOUNT | N11: SALES | Q11: POKIES
F12: =B12-(D12+L12) -> 0 | K12: =SUM(I12+J12+H12+G12)-F12 -> 0 | N12: TERMINAL | Q12: CASH BOX
F13: =B13-(D13+L13) -> 0 | K13: =SUM(I13+J13+H13+G13)-F13 -> 0 | N13: EBET 1 | Q13: TICKET IN
F14: =B14-(D14+L14) -> 0 | K14: =SUM(I14+J14+H14+G14)-F14 -> 0 | N14: EBET 2 | Q14: CASH IN | R14: =R12-R13 -> 0
A15: TOTALS | B15: =SUM(B12:B14) -> 0 | C15: =SUM(C12:C14) -> 0 | D15: =SUM(D12:D14) -> 0 | E15: =SUM(E12:E14) -> 0 | F15: =SUM(F12:F14) -> 0 | G15: =SUM(G12:G14) -> 0 | H15: =SUM(H12:H14) -> 0 | I15: =SUM(I12:I14) -> 0 | ... L15: =SUM(L12:L14) -> 0 | N15: TOTAL | O15: =SUM(O12:O14) -> 0 | Q15: MONEY OUT
G16: SPORTS TOTAL | J16: =SUM(I15+J15+H15+G15)-C15-E15 -> 0 | N16: LIABILITY | Q16: LINK AUTO
N17: TERMINAL | Q17: LINK MAN
A18: PUBLIC 1 | B18: READING | C18: FOOD | D18: TYRO FEE | E18: TIPS | F18: EXPECTED | G18: EFTPOS | H18: AMEX/DINER | I18: ME&U | J18: CASH | K18: VAR (+ / -) | L18: ACCOUNT | N18: EBET 1 | Q18: C/CREDITS
F19: =B19-(D19+L19) -> 0 | K19: =SUM(I19+J19+H19+G19)-F19 -> 0 | N19: EBET 2 | Q19: NET | R19: =R12-R15-R17-R18 -> 0
F20: =B20-(D20+L20) -> 0 | K20: =SUM(I20+J20+H20+G20)-F20 -> 0 | N20: TOTAL | O20: =SUM(O17:O19) -> 0 | Q20: TURNOVER
F21: =B21-(D21+L21) -> 0 | K21: =SUM(I21+J21+H21+G21)-F21 -> 0
A22: TOTALS | B22: =SUM(B19:B21) -> 0 | C22: =SUM(C19:C21) -> 0 | D22: =SUM(D19:D21) -> 0 | E22: =SUM(E19:E21) -> 0 | F22: =SUM(F19:F21) -> 0 | G22: =SUM(G19:G21) -> 0 | H22: =SUM(H19:H21) -> 0 | I22: =SUM(I19:I21) -> 0 | ... L22: =SUM(L19:L21) -> 0 | N22: EFTPOS
N23: =A11 -> SPORTS BAR | O23: =G15 -> 0 | Q23: TOTALS
A24: PUBLIC 2/GAMING | B24: READING | C24: FOOD | D24: TYRO FEE | E24: TIPS | F24: EXPECTED | G24: EFTPOS | H24: AMEX/DINER | I24: ME&U | J24: CASH | K24: VAR (+ / -) | L24: ACCOUNT | N24: =A4 -> BISTRO | O24: =G8 -> 0 | Q24: RECEIPTS | R24: =SUM(J29,J51,O7,J43,J16,J9,R19,J58,R9) -> 0
F25: =B25-(D25+L25) -> 0 | K25: =SUM(I25+J25+H25+G25)-F25 -> 0 | N25: B/SHOP | O25: =G50 -> 0 | Q25: GST | R25: =ROUND(+R24/11,2) -> 0
F26: =B26-(D26+L26) -> 0 | K26: =SUM(I26+J26+H26+G26)-F26 -> 0 | N26: PUBLIC 1 | O26: =G22 -> 0 | Q26: ATM | R26: =R39 -> 0
F27: =B27-(D27+L27) -> 0 | K27: =SUM(I27+J27+H27+G27)-F27 -> 0 | N27: PUBLIC 2 | O27: =G28 -> 0 | Q27: ME&U | R27: =I57+I42+I36+I28+I22+I15+I8 -> 0
A28: TOTALS | B28: =SUM(B25:B27) -> 0 | C28: =SUM(C25:C27) -> 0 | D28: =SUM(D25:D27) -> 0 | E28: =SUM(E25:E27) -> 0 | F28: =SUM(F25:F27) -> 0 | G28: =SUM(G25:G27) -> 0 | H28: =SUM(H25:H27) -> 0 | I28: =SUM(I25:I27) -> 0 | ... L28: =SUM(L25:L27) -> 0 | N28: ROOF TOP 1 | O28: =G36 -> 0 | Q28: EFTPOS | R28: =O31 -> 0
G29: PUBLIC BAR TOTAL | J29: =SUM(G22+H22+I22+J22)+(I28+J28+H28+G28)-C28-E28-C22-E22 -> 0 | N29: ROOF TOP 2 | O29: =G42 -> 0 | Q29: BANKING | R29: =R24-(R28+R26+R27) -> 0
N30: BISTRO | O30: =G57 -> 0
A31: TAYLORS BAR | N31: TOTAL | O31: =SUM(O23:O30) -> 0 | Q31: TAKING TIN | R31: =J8+J15+J22+J28+J36+J42+J50+J57 -> 0
A32: ROOF TOP 1 | B32: READING | C32: FOOD | D32: TYRO FEE | E32: TIPS | F32: EXPECTED | G32: EFTPOS | H32: AMEX/DINER | I32: ME&U | J32: CASH | K32: VAR (+ / -) | L32: ACCOUNT
F33: =B33-(D33+L33) -> 0 | K33: =SUM(I33+J33+H33+G33)-F33 -> 0 | Q33: TAB (ATM)
F34: =B34-(D34+L34) -> 0 | K34: =SUM(I34+J34+H34+G34)-F34 -> 0
F35: =B35-(D35+L35) -> 0 | K35: =SUM(I35+J35+H35+G35)-F35 -> 0
A36: TOTALS | B36: =SUM(B33:B35) -> 0 | C36: =SUM(C33:C35) -> 0 | D36: =SUM(D33:D35) -> 0 | E36: =SUM(E33:E35) -> 0 | F36: =SUM(F33:F35) -> 0 | G36: =SUM(G33:G35) -> 0 | H36: =SUM(H33:H35) -> 0 | I36: =SUM(I33:I35) -> 0 | ... L36: =SUM(L33:L35) -> 0 | Q36: ATM REFILL
Q37: ATM 1
A38: ROOF TOP 2 | B38: READING | C38: FOOD | D38: TYRO FEE | E38: TIPS | F38: EXPECTED | G38: EFTPOS | H38: AMEX/DINER | I38: ME&U | J38: CASH | K38: VAR (+ / -) | L38: ACCOUNT | Q38: ATM 2
F39: =B39-(D39+L39) -> 0 | K39: =SUM(I39+J39+H39+G39)-F39 -> 0 | Q39: TOTAL | R39: =SUM(R37:R38) -> 0
F40: =B40-(D40+L40) -> 0 | K40: =SUM(I40+J40+H40+G40)-F40 -> 0
...

Sheet Sun diary
A1: Republic Hotel
A2: =Sun!L3 -> 46061
A3: Weather -
A5: Summary | B5: Sunday | C5: Week to date | F5: Bars | G5: =SUM(G6:G9) -> 0
A6: Gaming Turnover | B6: =Takings!B30 -> 0 | C6: =SUM(Takings!B24:B30) -> 0 | F6: Public | G6: =Takings!C11 -> 0
A7: Gaming Gross | B7: =Takings!C30 -> 0 | C7: =SUM(Takings!C24:C30) -> 0 | F7: Bistro | G7: =Takings!D11 -> 0
A8: Gaming Net | B8: =Takings!I11 -> 0 | C8: =SUM(Takings!I5:I11) -> 0 | F8: Sports | G8: =Takings!E11 -> 0
A9: Dragon Link (50K) | F9: Taylors | G9: =Takings!F11 -> 0
A10: Dragon Train (20K)
A11: Fortune Hearts (25K)
A12: Dragon Rush (90K)
A13: Dragon Link (90K)
A14: Thunder Empire (50K) | F14: Bistro & Food Service
A15: Power Panther (12K) | F15: Day Covers | H15: Night Covers
A16: Bars | B16: =Takings!H46 -> 0 | C16: =SUM(Takings!B46:H46) -> 0 | F16: LUNCH Service Feedback
A17: Food | B17: =Takings!H49 -> 0 | C17: =SUM(Takings!B49:H49) -> 0
A18: Retail | B18: =Takings!H11 -> 0 | C18: =SUM(Takings!H5:H11) -> 0 | F18: Dinner Service Feedback
A19: TAB | B19: =Takings!L43 -> 0 | C19: =SUM(Takings!L37:L43) -> 0
F20: Public Bar
B21: DAY | C21: MID | D21: CLOSE | F21: Food | G21: =Sun!C22+Sun!C28 -> 0 | H21: Bev | I21: =Sun!J29 -> 0
A22: Managers Name | F22: Day
B23: GAMING
A24: Day turnover up to 6pm | B24: =G75 -> 0 | C24: Staff | F24: Evening
A25: How was the days trade
A26: Who were your big punters | F26: Late Night
A27: Large payouts/links & to whom
A28: Night turnover after 6pm | B28: =B6-B24 -> 0 | C28: Staff | F28: Bistro
A29: How was the night trade | F29: Food | G29: =Sun!C8 -> 0 | H29: Bev | I29: =Sun!J9 -> 0
A30: Who were your big punters | F30: Day
A31: Large payouts/links & to whom
B32: LINKS IF WON | F32: Evening
A33: What Link did they win
A34: How much was the Link | F34: Late Night
A35: What machine number
A36: How much were they betting | F36: Sports Bar
A37: Are they a regular | F37: Food | G37: =Sun!C15 -> 0 | H37: Bev | I37: =Sun!J16 -> 0
B38: AUSTRAC REPORTING | F38: Day
A39: Any Suspicious Customers
A40: Cash In to Turnover Ratio | B40: =Takings!B30/Takings!E30 -> #DIV/0! | F40: Evening
A41: Checked by
...

Sheet Takings
F1: Republic Hotel
O2: WEEK ENDING: | P2: =Sun!L3 -> 46061
A3: DATE | B3: DAY | C3: =Mon!A4 -> BISTRO | D3: =Mon!A11 -> SPORTS BAR | E3: PUBLIC | F3: TAYLORS | G3: FOOD | H3: =Mon!A45 -> BOTTLE SHOP | I3: POKIES NET | J3: SUNDRIES | K3: DETAILS | M3: TOTAL | N3: EFT/ATM | O3: BANKED | P3: GST
A5: =A6-1 -> 46055 | B5: MON | C5: =Mon!J9 -> 0 | D5: =Mon!J16 -> 0 | E5: =Mon!J29+Mon!J58 -> 0 | F5: =Mon!J43 -> 0 | G5: =B49 -> 0 | H5: =Mon!J51 -> 0 | I5: =Mon!R19 -> 0 | J5: =Mon!O7 -> 0 | M5: =SUM(C5:J5) -> 0 | N5: =T24 -> 0 | O5: =M5-N5 -> 0 | P5: =M5/11 -> 0
A6: =A7-1 -> 46056 | B6: TUE | C6: =Tue!J9 -> 0 | D6: =Tue!J16 -> 0 | E6: =Tue!J29+Tue!J58 -> 0 | F6: =Tue!J43 -> 0 | G6: =C49 -> 0 | H6: =Tue!J51 -> 0 | I6: =Tue!R19 -> 0 | J6: =Tue!O7 -> 0 | M6: =SUM(C6:J6) -> 0 | N6: =T25 -> 0 | O6: =M6-N6 -> 0 | P6: =M6/11 -> 0
A7: =A8-1 -> 46057 | B7: WED | C7: =Wed!J9 -> 0 | D7: =Wed!J16 -> 0 | E7: =Wed!J29+Wed!J58 -> 0 | F7: =Wed!J43 -> 0 | G7: =D49 -> 0 | H7: =Wed!J51 -> 0 | I7: =Wed!R19 -> 0 | J7: =Wed!O7 -> 0 | M7: =SUM(C7:J7) -> 0 | N7: =T26 -> 0 | O7: =M7-N7 -> 0 | P7: =M7/11 -> 0
A8: =A9-1 -> 46058 | B8: THUR | C8: =Thu!J9 -> 0 | D8: =Thu!J16 -> 0 | E8: =Thu!J29+Thu!J58 -> 0 | F8: =Thu!J43 -> 0 | G8: =E49 -> 0 | H8: =Thu!J51 -> 0 | I8: =Thu!R19 -> 0 | J8: =Thu!O7 -> 0 | M8: =SUM(C8:J8) -> 0 | N8: =T27 -> 0 | O8: =M8-N8 -> 0 | P8: =M8/11 -> 0
A9: =A10-1 -> 46059 | B9: FRI | C9: =Fri!J9 -> 0 | D9: =Fri!J16 -> 0 | E9: =Fri!J29+Fri!J58 -> 0 | F9: =Fri!J43 -> 0 | G9: =F49 -> 0 | H9: =Fri!J51 -> 0 | I9: =Fri!R19 -> 0 | J9: =Fri!O7 -> 0 | M9: =SUM(C9:J9) -> 0 | N9: =T28 -> 0 | O9: =M9-N9 -> 0 | P9: =M9/11 -> 0
A10: =A11-1 -> 46060 | B10: SAT | C10: =Sat!J9 -> 0 | D10: =Sat!J16 -> 0 | E10: =Sat!J29+Sat!J58 -> 0 | F10: =Sat!J43 -> 0 | G10: =G49 -> 0 | H10: =Sat!J51 -> 0 | I10: =Sat!R19 -> 0 | J10: =Sat!O7 -> 0 | M10: =SUM(C10:J10) -> 0 | N10: =T29 -> 0 | O10: =M10-N10 -> 0 | P10: =M10/11 -> 0
A11: =P2 -> 46061 | B11: SUN | C11: =Sun!J9 -> 0 | D11: =Sun!J16 -> 0 | E11: =Sun!J29+Sun!J58 -> 0 | F11: =Sun!J43 -> 0 | G11: =H49 -> 0 | H11: =Sun!J51 -> 0 | I11: =Sun!R19 -> 0 | J11: =Sun!O7 -> 0 | K11: TAB COMMISSION | M11: =SUM(C11:J11) -> 0 | N11: =T30 -> 0 | O11: =M11-N11 -> 0 | P11: =M11/11 -> 0
A12: TOTAL | C12: =SUM(C5:C11) -> 0 | D12: =SUM(D5:D11) -> 0 | E12: =SUM(E5:E11) -> 0 | F12: =SUM(F5:F11) -> 0 | G12: =SUM(G5:G11) -> 0 | H12: =SUM(H5:H11) -> 0 | I12: =SUM(I5:I11) -> 0 | J12: =SUM(J5:J11) -> 0 | M12: =SUM(M5:M11) -> 0 | N12: =SUM(N5:N11) -> 0 | O12: =SUM(O5:O11) -> 0 | P12: =SUM(P5:P11) -> 0
A14: GST | C14: =C12/11 -> 0 | D14: =D12/11 -> 0 | E14: =E12/11 -> 0 | F14: =F12/11 -> 0 | G14: =G12/11 -> 0 | H14: =H12/11 -> 0 | I14: =I12/11 -> 0 | J14: =J12/11 -> 0 | M14: =M12/11 -> 0 | O14: GST CHECK | P14: =M14-P12 -> 0
A16: BALANCE | C16: =C12-C14 -> 0 | D16: =D12-D14 -> 0 | E16: =E12-E14 -> 0 | F16: =F12-F14 -> 0 | G16: =G12-G14 -> 0 | H16: =H12-H14 -> 0 | I16: =I12-I14 -> 0 | J16: =J12-J14 -> 0 | M16: =M12-M14 -> 0
A18: POS
A19: TYRO SURCHARGE | C19: =SUM(Mon!D8+Tue!D8+Wed!D8+Thu!D8+Fri!D8+Sat!D8+Sun!D8) -> 0 | D19: =SUM(Mon!D15+Tue!D15+Wed!D15+Thu!D15+Fri!D15+Sat!D15+Sun!D15) -> 0 | E19: =SUM(Mon!D22+Mon!D28+Tue!D22+Tue!D28+Wed!D22+Wed!D28+Thu!D22+Thu!D28+Fri!D22+Fri!D28+Sat!D22+Sat!D28+Sun!D22+Sun!D28)+(Mon!D57+Tue!D57+Wed!D57+Thu!D57+Fri!D57+Sat!D57+Sun!D57) -> 0 | F19: =SUM(Mon!D36+Mon!D42+Tue!D36+Tue!D42+Wed!D36+Wed!D42+Thu!D36+Thu!D42+Fri!D36+Fri!D42+Sat!D36+Sat!D42+Sun!D36+Sun!D42) -> 0 | G19: =SUM(Mon!D57+Tue!D57+Wed!D57+Thu!D57+Fri!D57+Sat!D57+Sun!D57) -> 0 | H19: =SUM(Mon!D50+Tue!D50+Wed!D50+Thu!D50+Fri!D50+Sat!D50+Sun!D50) -> 0
A20: TILL TOTAL | C20: =C18-C19 -> 0 | D20: =D18-D19 -> 0 | E20: =E18-E19 -> 0 | F20: =F18-F19 -> 0 | G20: =G18-G19 -> 0 | H20: =H18-H19 -> 0
A21: VAR +/- | C21: =C12-C20 -> 0 | D21: =D12-D20 -> 0 | E21: =E12-E20 -> 0 | F21: =F12-F20 -> 0 | G21: =G12 -> 0 | H21: =H12-H20 -> 0
J22: ATM/EFTPOS
A23: GAMING | B23: TURNOVER | C23: GROSS | D23: TICKET IN | E23: CASH IN | F23: PAID OUT | G23: LINKS | H23: NET | J23: =C3 -> BISTRO | K23: =D3 -> SPORTS BAR | L23: B/SHOP | M23: PUBLIC 1 | N23: PUBLIC 2 | O23: ROOF TOP 1 | P23: ROOF TOP 2 | Q23: BISTRO | R23: ME&U | S23: ATM | T23: TOTAL
A24: MON | B24: =Mon!R20 -> 0 | C24: =Mon!R12 -> 0 | D24: =Mon!R13 -> 0 | E24: =Mon!R14 -> 0 | F24: =Mon!R15+Mon!R18 -> 0 | G24: =Mon!R16+Mon!R17 -> 0 | H24: =Mon!R19 -> 0 | J24: =Mon!O24 -> 0 | K24: =Mon!O23 -> 0 | L24: =Mon!O25 -> 0 | M24: =Mon!O26 -> 0 | N24: =Mon!O27 -> 0 | O24: =Mon!O28 -> 0 | P24: =Mon!O29 -> 0 | Q24: =Mon!O30 -> 0 | R24: =Mon!R27 -> 0 | S24: =Mon!R26 -> 0 | T24: =SUM(J24:S24) -> 0
A25: TUE | B25: =Tue!R20 -> 0 | C25: =Tue!R12 -> 0 | D25: =Tue!R13 -> 0 | E25: =Tue!R14 -> 0 | F25: =Tue!R15+Tue!R18 -> 0 | G25: =Tue!R16+Tue!R17 -> 0 | H25: =Tue!R19 -> 0 | J25: =Tue!O24 -> 0 | K25: =Tue!O23 -> 0 | L25: =Tue!O25 -> 0 | M25: =Tue!O26 -> 0 | N25: =Tue!O27 -> 0 | O25: =Tue!O28 -> 0 | P25: =Tue!O29 -> 0 | Q25: =Tue!O30 -> 0 | R25: =Tue!R27 -> 0 | S25: =Tue!R26 -> 0 | T25: =SUM(J25:S25) -> 0
A26: WED | B26: =Wed!R20 -> 0 | C26: =Wed!R12 -> 0 | D26: =Wed!R13 -> 0 | E26: =Wed!R14 -> 0 | F26: =Wed!R15+Wed!R18 -> 0 | G26: =Wed!R16+Wed!R17 -> 0 | H26: =Wed!R19 -> 0 | J26: =Wed!O24 -> 0 | K26: =Wed!O23 -> 0 | L26: =Wed!O25 -> 0 | M26: =Wed!O26 -> 0 | N26: =Wed!O27 -> 0 | O26: =Wed!O28 -> 0 | P26: =Wed!O29 -> 0 | Q26: =Wed!O30 -> 0 | R26: =Wed!R27 -> 0 | S26: =Wed!R26 -> 0 | T26: =SUM(J26:S26) -> 0
A27: THUR | B27: =Thu!R20 -> 0 | C27: =Thu!R12 -> 0 | D27: =Thu!R13 -> 0 | E27: =Thu!R14 -> 0 | F27: =Thu!R15+Thu!R18 -> 0 | G27: =Thu!R16+Thu!R17 -> 0 | H27: =Thu!R19 -> 0 | J27: =Thu!O24 -> 0 | K27: =Thu!O23 -> 0 | L27: =Thu!O25 -> 0 | M27: =Thu!O26 -> 0 | N27: =Thu!O27 -> 0 | O27: =Thu!O28 -> 0 | P27: =Thu!O29 -> 0 | Q27: =Thu!O30 -> 0 | R27: =Thu!R27 -> 0 | S27: =Thu!R26 -> 0 | T27: =SUM(J27:S27) -> 0
A28: FRI | B28: =Fri!R20 -> 0 | C28: =Fri!R12 -> 0 | D28: =Fri!R13 -> 0 | E28: =Fri!R14 -> 0 | F28: =Fri!R15+Fri!R18 -> 0 | G28: =Fri!R16+Fri!R17 -> 0 | H28: =Fri!R19 -> 0 | J28: =Fri!O24 -> 0 | K28: =Fri!O23 -> 0 | L28: =Fri!O25 -> 0 | M28: =Fri!O26 -> 0 | N28: =Fri!O27 -> 0 | O28: =Fri!O28 -> 0 | P28: =Fri!O29 -> 0 | Q28: =Fri!O30 -> 0 | R28: =Fri!R27 -> 0 | S28: =Fri!R26 -> 0 | T28: =SUM(J28:S28) -> 0
A29: SAT | B29: =Sat!R20 -> 0 | C29: =Sat!R12 -> 0 | D29: =Sat!R13 -> 0 | E29: =Sat!R14 -> 0 | F29: =Sat!R15+Sat!R18 -> 0 | G29: =Sat!R16+Sat!R17 -> 0 | H29: =Sat!R19 -> 0 | J29: =Sat!O24 -> 0 | K29: =Sat!O23 -> 0 | L29: =Sat!O25 -> 0 | M29: =Sat!O26 -> 0 | N29: =Sat!O27 -> 0 | O29: =Sat!O28 -> 0 | P29: =Sat!O29 -> 0 | Q29: =Sat!O30 -> 0 | R29: =Sat!R27 -> 0 | S29: =Sat!R26 -> 0 | T29: =SUM(J29:S29) -> 0
A30: SUN | B30: =Sun!R20 -> 0 | C30: =Sun!R12 -> 0 | D30: =Sun!R13 -> 0 | E30: =Sun!R14 -> 0 | F30: =Sun!R15+Sun!R18 -> 0 | G30: =Sun!R16+Sun!R17 -> 0 | H30: =Sun!R19 -> 0 | J30: =Sun!O24 -> 0 | K30: =Sun!O23 -> 0 | L30: =Sun!O25 -> 0 | M30: =Sun!O26 -> 0 | N30: =Sun!O27 -> 0 | O30: =Sun!O28 -> 0 | P30: =Sun!O29 -> 0 | Q30: =Sun!O30 -> 0 | R30: =Sun!R27 -> 0 | S30: =Sun!R26 -> 0 | T30: =SUM(J30:S30) -> 0
A31: TOTALS | B31: =SUM(B24:B30) -> 0 | C31: =SUM(C24:C30) -> 0 | D31: =SUM(D24:D30) -> 0 | E31: =SUM(E24:E30) -> 0 | F31: =SUM(F24:F30) -> 0 | G31: =SUM(G24:G30) -> 0 | H31: =SUM(H24:H30) -> 0 | J31: =SUM(J24:J30) -> 0 | K31: =SUM(K24:K30) -> 0 | L31: =SUM(L24:L30) -> 0 | M31: =SUM(M24:M30) -> 0 | N31: =SUM(N24:N30) -> 0 | O31: =SUM(O24:O30) -> 0 | P31: =SUM(P24:P30) -> 0 | Q31: =SUM(Q24:Q30) -> 0 | ... T31: =SUM(T24:T30) -> 0
A32: GLOBAL
A33: VAR +/- | B33: =B31-B32 -> 0 | C33: =C31-C32 -> 0 | D33: =D31-D32 -> 0 | E33: =E31-E32 -> 0 | F33: =F31-F32 -> 0 | G33: =G31-G32 -> 0
L35: TAB | Q35: TAB
A36: TARGETS | L36: SALES | M36: LIABILITY | N36: CUMM DAILY | O36: VAR | Q36: ATM
A37: DEPT | B37: TARGET | C37: ACTUAL | D37: VAR | E37: REASONS | L37: =Mon!O15 -> 0 | M37: =Mon!O20 -> 0 | O37: =SUM(M36:M37)-N36:N37 -> 0 | Q37: =Mon!R33 -> 0
A38: TURNOVER | B38: 1000000 | C38: =B31 -> 0 | D38: =SUM(C38-B38) -> -1000000 | L38: =Tue!O15 -> 0 | M38: =Tue!O20 -> 0 | O38: =SUM(M37:M38)-N37:N38 -> 0 | Q38: =Tue!R33 -> 0
A39: BAR | B39: 75000 | C39: =I46 -> 0 | D39: =C39-B39 -> -75000 | L39: =Wed!O15 -> 0 | M39: =Wed!O20 -> 0 | O39: =SUM(M37:M39)-N37:N39 -> 0 | Q39: =Wed!R33 -> 0
A40: RETAIL | B40: 0 | C40: =H12 -> 0 | D40: =C40-B40 -> 0 | L40: =Thu!O15 -> 0 | M40: =Thu!O20 -> 0 | O40: =SUM(M37:M40)-N37:N40 -> 0 | Q40: =Thu!R33 -> 0
A41: WAGES | B41: 32000 | D41: =C41-B41 -> -32000 | L41: =Fri!O15 -> 0 | M41: =Fri!O20 -> 0 | O41: =SUM(M37:M41)-N37:N41 -> 0 | Q41: =Fri!R33 -> 0
A42: SECURITY | B42: 3000 | D42: =C42-B42 -> -3000 | L42: =Sat!O15 -> 0 | M42: =Sat!O20 -> 0 | O42: =SUM(M37:M42)-N37:N42 -> 0 | Q42: =Sat!R33 -> 0
L43: =Sun!O15 -> 0 | M43: =Sun!O20 -> 0 | O43: =SUM(M37:M43)-N37:N43 -> 0 | Q43: =Sun!R33 -> 0
L44: =SUM(L37:L43) -> 0 | M44: =SUM(M37:M43) -> 0 | P44: TOTAL | Q44: =SUM(Q37:Q43) -> 0
B45: MON | C45: TUE | D45: WED | E45: THUR | F45: FRI | G45: SAT | H45: SUN | I45: TOTAL | L45: AGENT FEE
...

Sheet Safe Count
A1: REPUBLIC SAFE COUNT
A2: DAY | B2: Monday | C2: Monday
A3: DATE | B3: 46041
A4: TIME | B4: Rollover
